Workbook
Name bp: 'Opp Name'!$R$7
Name bp: 'Opportunity_Name USD'!$R$7
Name bpusd: #REF!
Name iconn: 'Opp Name'!$R$6
Name iconn: 'Opportunity_Name USD'!$R$6
Name iconnusd: #REF!
Name isaas: 'Opp Name'!$R$4
Name isaas: 'Opportunity_Name USD'!$R$4
Name isaasusd: #REF!
Name iserv: 'Opp Name'!$R$5
Name iserv: 'Opportunity_Name USD'!$R$5
Name iservusd: #REF!

Sheet Opp Name
B2: CXONE DIGITAL AGENT - 36 Meses
B4: SOFTWARE MRC PRODUCTS | H4: PRICE LIST | J4: FOB NET PRICE | N4: SELL PRICE (WITH TAXES) | Q4: Imposto de Licença | R4: 0.1383
B5: # | C5: Product | D5: SKU | E5: Quantity | F5: Group | G5: Prod Category Discount | H5: Unit Partner Price | I5: Total Partner Price | J5: Additional Discount | K5: Unit Price (FOB) | L5: 5.8 | M5: FOB NET | N5: Unit Sell Price | O5: Total Sell Price | Q5: Imposto de Serviço | R5: 0.0701
B6: 1 | I6: =H6*E6 -> 0 | J6: {=IFERROR(_xlfn.SWITCH(G6, $Q$10, $R$10, $Q$11, $R$11, $Q$12, $R$12, $Q$13, $R$13, $Q$14, $R$14, $Q$15, $R$15, $Q$16, $R$16, $Q$17, $R$17, $Q$18, $R$18,$Q$19,$R$19,$Q$20,$R$20,$Q$21,$R$21,$Q$22,$R$22,$Q$23,$R$23,$Q$24,$R$24), 0)} -> 0 | K6: =IFERROR(H6*(1-J6),0) -> 0 | L6: =IFERROR(K6*E6,0)/$L$5 -> 0 | M6: =IFERROR(K6*E6,0) -> 0 | N6: {=IFERROR(K6*(1+IFERROR(_xlfn.SWITCH(G6, $Q$10, $S$10, $Q$11, $S$11, $Q$12, $S$12, $Q$13, $S$13, $Q$14, $S$14, $Q$15, $S$15, $Q$16, $S$16, $Q$17, $S$17, $Q$18, $S$18,$Q$19,$S$19,$Q$20,$S$20,$Q$21,$S$21,$Q$22,$S$22,$Q$23,$S$23,$Q$24,$S$24), $S$10))*bp, 0)} -> 0 | O6: =IFERROR(N6*E6,0) -> 0 | Q6: Imposto Conn MPLS | R6: 0.11
B7: 2 | I7: =H7*E7 -> 0 | J7: {=IFERROR(_xlfn.SWITCH(G7, $Q$10, $R$10, $Q$11, $R$11, $Q$12, $R$12, $Q$13, $R$13, $Q$14, $R$14, $Q$15, $R$15, $Q$16, $R$16, $Q$17, $R$17, $Q$18, $R$18,$Q$19,$R$19,$Q$20,$R$20,$Q$21,$R$21,$Q$22,$R$22,$Q$23,$R$23,$Q$24,$R$24), 0)} -> 0 | K7: =IFERROR(H7*(1-J7),0) -> 0 | L7: =IFERROR(K7*E7,0)/$L$5 -> 0 | M7: =IFERROR(K7*E7,0) -> 0 | N7: {=IFERROR(K7*(1+IFERROR(_xlfn.SWITCH(G7, $Q$10, $S$10, $Q$11, $S$11, $Q$12, $S$12, $Q$13, $S$13, $Q$14, $S$14, $Q$15, $S$15, $Q$16, $S$16, $Q$17, $S$17, $Q$18, $S$18,$Q$19,$S$19,$Q$20,$S$20,$Q$21,$S$21,$Q$22,$S$22,$Q$23,$S$23,$Q$24,$S$24), $S$10))*bp, 0)} -> 0 | O7: =IFERROR(N7*E7,0) -> 0 | Q7: BP Factor | R7: 1
B8: 3 | I8: =H8*E8 -> 0 | J8: {=IFERROR(_xlfn.SWITCH(G8, $Q$10, $R$10, $Q$11, $R$11, $Q$12, $R$12, $Q$13, $R$13, $Q$14, $R$14, $Q$15, $R$15, $Q$16, $R$16, $Q$17, $R$17, $Q$18, $R$18,$Q$19,$R$19,$Q$20,$R$20,$Q$21,$R$21,$Q$22,$R$22,$Q$23,$R$23,$Q$24,$R$24), 0)} -> 0 | K8: =IFERROR(H8*(1-J8),0) -> 0 | L8: =IFERROR(K8*E8,0)/$L$5 -> 0 | M8: =IFERROR(K8*E8,0) -> 0 | N8: {=IFERROR(K8*(1+IFERROR(_xlfn.SWITCH(G8, $Q$10, $S$10, $Q$11, $S$11, $Q$12, $S$12, $Q$13, $S$13, $Q$14, $S$14, $Q$15, $S$15, $Q$16, $S$16, $Q$17, $S$17, $Q$18, $S$18,$Q$19,$S$19,$Q$20,$S$20,$Q$21,$S$21,$Q$22,$S$22,$Q$23,$S$23,$Q$24,$S$24), $S$10))*bp, 0)} -> 0 | O8: =IFERROR(N8*E8,0) -> 0
B9: 4 | I9: =H9*E9 -> 0 | J9: {=IFERROR(_xlfn.SWITCH(G9, $Q$10, $R$10, $Q$11, $R$11, $Q$12, $R$12, $Q$13, $R$13, $Q$14, $R$14, $Q$15, $R$15, $Q$16, $R$16, $Q$17, $R$17, $Q$18, $R$18,$Q$19,$R$19,$Q$20,$R$20,$Q$21,$R$21,$Q$22,$R$22,$Q$23,$R$23,$Q$24,$R$24), 0)} -> 0 | K9: =IFERROR(H9*(1-J9),0) -> 0 | L9: =IFERROR(K9*E9,0)/$L$5 -> 0 | M9: =IFERROR(K9*E9,0) -> 0 | N9: {=IFERROR(K9*(1+IFERROR(_xlfn.SWITCH(G9, $Q$10, $S$10, $Q$11, $S$11, $Q$12, $S$12, $Q$13, $S$13, $Q$14, $S$14, $Q$15, $S$15, $Q$16, $S$16, $Q$17, $S$17, $Q$18, $S$18,$Q$19,$S$19,$Q$20,$S$20,$Q$21,$S$21,$Q$22,$S$22,$Q$23,$S$23,$Q$24,$S$24), $S$10))*bp, 0)} -> 0 | O9: =IFERROR(N9*E9,0) -> 0 | R9: Discount | S9: Local Taxes | U9: Group | V9: Quantity | W9: List Price BRL | X9: Price per license BRL | Y9: Discounted Price BRL | Z9: Discounted Price per license BRL
B10: 5 | I10: =H10*E10 -> 0 | J10: {=IFERROR(_xlfn.SWITCH(G10, $Q$10, $R$10, $Q$11, $R$11, $Q$12, $R$12, $Q$13, $R$13, $Q$14, $R$14, $Q$15, $R$15, $Q$16, $R$16, $Q$17, $R$17, $Q$18, $R$18,$Q$19,$R$19,$Q$20,$R$20,$Q$21,$R$21,$Q$22,$R$22,$Q$23,$R$23,$Q$24,$R$24), 0)} -> 0 | K10: =IFERROR(H10*(1-J10),0) -> 0 | L10: =IFERROR(K10*E10,0)/$L$5 -> 0 | M10: =IFERROR(K10*E10,0) -> 0 | N10: {=IFERROR(K10*(1+IFERROR(_xlfn.SWITCH(G10, $Q$10, $S$10, $Q$11, $S$11, $Q$12, $S$12, $Q$13, $S$13, $Q$14, $S$14, $Q$15, $S$15, $Q$16, $S$16, $Q$17, $S$17, $Q$18, $S$18,$Q$19,$S$19,$Q$20,$S$20,$Q$21,$S$21,$Q$22,$S$22,$Q$23,$S$23,$Q$24,$S$24), $S$10))*bp, 0)} -> 0 | O10: =IFERROR(N10*E10,0) -> 0 | Q10: Bundle | R10: 0 | S10: =isaas -> 0.1383 | U10: Bundle | V10: ='Opp Name'!$E$6 -> 0 | W10: =SUMIF('Opp Name'!$F:$F,Table14[[#This Row],[Group]],'Opp Name'!$I:$I) -> 0 | X10: =W10/V10 -> #DIV/0! | Y10: =SUMIF('Opp Name'!$F:$F,Table14[[#This Row],[Group]],'Opp Name'!$M:$M) -> 0 | Z10: =Y10/V10 -> #DIV/0!
B11: 6 | I11: =H11*E11 -> 0 | J11: {=IFERROR(_xlfn.SWITCH(G11, $Q$10, $R$10, $Q$11, $R$11, $Q$12, $R$12, $Q$13, $R$13, $Q$14, $R$14, $Q$15, $R$15, $Q$16, $R$16, $Q$17, $R$17, $Q$18, $R$18,$Q$19,$R$19,$Q$20,$R$20,$Q$21,$R$21,$Q$22,$R$22,$Q$23,$R$23,$Q$24,$R$24), 0)} -> 0 | K11: =IFERROR(H11*(1-J11),0) -> 0 | L11: =IFERROR(K11*E11,0)/$L$5 -> 0 | M11: =IFERROR(K11*E11,0) -> 0 | N11: {=IFERROR(K11*(1+IFERROR(_xlfn.SWITCH(G11, $Q$10, $S$10, $Q$11, $S$11, $Q$12, $S$12, $Q$13, $S$13, $Q$14, $S$14, $Q$15, $S$15, $Q$16, $S$16, $Q$17, $S$17, $Q$18, $S$18,$Q$19,$S$19,$Q$20,$S$20,$Q$21,$S$21,$Q$22,$S$22,$Q$23,$S$23,$Q$24,$S$24), $S$10))*bp, 0)} -> 0 | O11: =IFERROR(N11*E11,0) -> 0 | Q11: Integrated SW | R11: 0 | S11: =isaas -> 0.1383 | U11: Success Package | V11: ='Opp Name'!$E$6 -> 0 | W11: =SUMIF('Opp Name'!$F:$F,Table14[[#This Row],[Group]],'Opp Name'!$I:$I) -> 0 | X11: =W11/V11 -> #DIV/0! | Y11: =SUMIF('Opp Name'!$F:$F,Table14[[#This Row],[Group]],'Opp Name'!$M:$M) -> 0 | Z11: =Y11/V11 -> #DIV/0!
B12: 7 | I12: =H12*E12 -> 0 | J12: {=IFERROR(_xlfn.SWITCH(G12, $Q$10, $R$10, $Q$11, $R$11, $Q$12, $R$12, $Q$13, $R$13, $Q$14, $R$14, $Q$15, $R$15, $Q$16, $R$16, $Q$17, $R$17, $Q$18, $R$18,$Q$19,$R$19,$Q$20,$R$20,$Q$21,$R$21,$Q$22,$R$22,$Q$23,$R$23,$Q$24,$R$24), 0)} -> 0 | K12: =IFERROR(H12*(1-J12),0) -> 0 | L12: =IFERROR(K12*E12,0)/$L$5 -> 0 | M12: =IFERROR(K12*E12,0) -> 0 | N12: {=IFERROR(K12*(1+IFERROR(_xlfn.SWITCH(G12, $Q$10, $S$10, $Q$11, $S$11, $Q$12, $S$12, $Q$13, $S$13, $Q$14, $S$14, $Q$15, $S$15, $Q$16, $S$16, $Q$17, $S$17, $Q$18, $S$18,$Q$19,$S$19,$Q$20,$S$20,$Q$21,$S$21,$Q$22,$S$22,$Q$23,$S$23,$Q$24,$S$24), $S$10))*bp, 0)} -> 0 | O12: =IFERROR(N12*E12,0) -> 0 | Q12: CXone SW | R12: 0 | S12: =isaas -> 0.1383 | U12: Video/Co-browse | V12: ='Opp Name'!$E$6 -> 0 | W12: =SUMIF('Opp Name'!$F:$F,Table14[[#This Row],[Group]],'Opp Name'!$I:$I) -> 0 | X12: =W12/V12 -> #DIV/0! | Y12: =SUMIF('Opp Name'!$F:$F,Table14[[#This Row],[Group]],'Opp Name'!$M:$M) -> 0 | Z12: =Y12/V12 -> #DIV/0!
B13: 8 | I13: =H13*E13 -> 0 | J13: {=IFERROR(_xlfn.SWITCH(G13, $Q$10, $R$10, $Q$11, $R$11, $Q$12, $R$12, $Q$13, $R$13, $Q$14, $R$14, $Q$15, $R$15, $Q$16, $R$16, $Q$17, $R$17, $Q$18, $R$18,$Q$19,$R$19,$Q$20,$R$20,$Q$21,$R$21,$Q$22,$R$22,$Q$23,$R$23,$Q$24,$R$24), 0)} -> 0 | K13: =IFERROR(H13*(1-J13),0) -> 0 | L13: =IFERROR(K13*E13,0)/$L$5 -> 0 | M13: =IFERROR(K13*E13,0) -> 0 | N13: {=IFERROR(K13*(1+IFERROR(_xlfn.SWITCH(G13, $Q$10, $S$10, $Q$11, $S$11, $Q$12, $S$12, $Q$13, $S$13, $Q$14, $S$14, $Q$15, $S$15, $Q$16, $S$16, $Q$17, $S$17, $Q$18, $S$18,$Q$19,$S$19,$Q$20,$S$20,$Q$21,$S$21,$Q$22,$S$22,$Q$23,$S$23,$Q$24,$S$24), $S$10))*bp, 0)} -> 0 | O13: =IFERROR(N13*E13,0) -> 0 | Q13: Services | R13: 0 | S13: =iserv -> 0.0701 | U13: Dialer | V13: ='Opp Name'!$E$6 -> 0 | W13: =SUMIF('Opp Name'!$F:$F,Table14[[#This Row],[Group]],'Opp Name'!$I:$I) -> 0 | X13: =W13/V13 -> #DIV/0! | Y13: =SUMIF('Opp Name'!$F:$F,Table14[[#This Row],[Group]],'Opp Name'!$M:$M) -> 0 | Z13: =Y13/V13 -> #DIV/0!
B14: 9 | I14: =H14*E14 -> 0 | J14: {=IFERROR(_xlfn.SWITCH(G14, $Q$10, $R$10, $Q$11, $R$11, $Q$12, $R$12, $Q$13, $R$13, $Q$14, $R$14, $Q$15, $R$15, $Q$16, $R$16, $Q$17, $R$17, $Q$18, $R$18,$Q$19,$R$19,$Q$20,$R$20,$Q$21,$R$21,$Q$22,$R$22,$Q$23,$R$23,$Q$24,$R$24), 0)} -> 0 | K14: =IFERROR(H14*(1-J14),0) -> 0 | L14: =IFERROR(K14*E14,0)/$L$5 -> 0 | M14: =IFERROR(K14*E14,0) -> 0 | N14: {=IFERROR(K14*(1+IFERROR(_xlfn.SWITCH(G14, $Q$10, $S$10, $Q$11, $S$11, $Q$12, $S$12, $Q$13, $S$13, $Q$14, $S$14, $Q$15, $S$15, $Q$16, $S$16, $Q$17, $S$17, $Q$18, $S$18,$Q$19,$S$19,$Q$20,$S$20,$Q$21,$S$21,$Q$22,$S$22,$Q$23,$S$23,$Q$24,$S$24), $S$10))*bp, 0)} -> 0 | O14: =IFERROR(N14*E14,0) -> 0 | Q14: Support | R14: 0 | S14: =isaas -> 0.1383 | U14: WFM IEX | V14: ='Opp Name'!$E$6 -> 0 | W14: =SUMIF('Opp Name'!$F:$F,Table14[[#This Row],[Group]],'Opp Name'!$I:$I) -> 0 | X14: =W14/V14 -> #DIV/0! | Y14: =SUMIF('Opp Name'!$F:$F,Table14[[#This Row],[Group]],'Opp Name'!$M:$M) -> 0 | Z14: =Y14/V14 -> #DIV/0!
B15: 10 | I15: =H15*E15 -> 0 | J15: {=IFERROR(_xlfn.SWITCH(G15, $Q$10, $R$10, $Q$11, $R$11, $Q$12, $R$12, $Q$13, $R$13, $Q$14, $R$14, $Q$15, $R$15, $Q$16, $R$16, $Q$17, $R$17, $Q$18, $R$18,$Q$19,$R$19,$Q$20,$R$20,$Q$21,$R$21,$Q$22,$R$22,$Q$23,$R$23,$Q$24,$R$24), 0)} -> 0 | K15: =IFERROR(H15*(1-J15),0) -> 0 | L15: =IFERROR(K15*E15,0)/$L$5 -> 0 | M15: =IFERROR(K15*E15,0) -> 0 | N15: {=IFERROR(K15*(1+IFERROR(_xlfn.SWITCH(G15, $Q$10, $S$10, $Q$11, $S$11, $Q$12, $S$12, $Q$13, $S$13, $Q$14, $S$14, $Q$15, $S$15, $Q$16, $S$16, $Q$17, $S$17, $Q$18, $S$18,$Q$19,$S$19,$Q$20,$S$20,$Q$21,$S$21,$Q$22,$S$22,$Q$23,$S$23,$Q$24,$S$24), $S$10))*bp, 0)} -> 0 | O15: =IFERROR(N15*E15,0) -> 0 | Q15: Success Package | R15: 0 | S15: =isaas -> 0.1383 | U15: Knowledge | V15: ='Opp Name'!$E$6 -> 0 | W15: =SUMIF('Opp Name'!$F:$F,Table14[[#This Row],[Group]],'Opp Name'!$I:$I) -> 0 | X15: =W15/V15 -> #DIV/0! | Y15: =SUMIF('Opp Name'!$F:$F,Table14[[#This Row],[Group]],'Opp Name'!$M:$M) -> 0 | Z15: =Y15/V15 -> #DIV/0!
B16: 11 | I16: =H16*E16 -> 0 | J16: {=IFERROR(_xlfn.SWITCH(G16, $Q$10, $R$10, $Q$11, $R$11, $Q$12, $R$12, $Q$13, $R$13, $Q$14, $R$14, $Q$15, $R$15, $Q$16, $R$16, $Q$17, $R$17, $Q$18, $R$18,$Q$19,$R$19,$Q$20,$R$20,$Q$21,$R$21,$Q$22,$R$22,$Q$23,$R$23,$Q$24,$R$24), 0)} -> 0 | K16: =IFERROR(H16*(1-J16),0) -> 0 | L16: =IFERROR(K16*E16,0)/$L$5 -> 0 | M16: =IFERROR(K16*E16,0) -> 0 | N16: {=IFERROR(K16*(1+IFERROR(_xlfn.SWITCH(G16, $Q$10, $S$10, $Q$11, $S$11, $Q$12, $S$12, $Q$13, $S$13, $Q$14, $S$14, $Q$15, $S$15, $Q$16, $S$16, $Q$17, $S$17, $Q$18, $S$18,$Q$19,$S$19,$Q$20,$S$20,$Q$21,$S$21,$Q$22,$S$22,$Q$23,$S$23,$Q$24,$S$24), $S$10))*bp, 0)} -> 0 | O16: =IFERROR(N16*E16,0) -> 0 | Q16: Others | R16: 0 | S16: =isaas -> 0.1383 | U16: Gamification | V16: ='Opp Name'!$E$6 -> 0 | W16: =SUMIF('Opp Name'!$F:$F,Table14[[#This Row],[Group]],'Opp Name'!$I:$I) -> 0 | X16: =W16/V16 -> #DIV/0! | Y16: =SUMIF('Opp Name'!$F:$F,Table14[[#This Row],[Group]],'Opp Name'!$M:$M) -> 0 | Z16: =Y16/V16 -> #DIV/0!
B17: 12 | I17: =H17*E17 -> 0 | J17: {=IFERROR(_xlfn.SWITCH(G17, $Q$10, $R$10, $Q$11, $R$11, $Q$12, $R$12, $Q$13, $R$13, $Q$14, $R$14, $Q$15, $R$15, $Q$16, $R$16, $Q$17, $R$17, $Q$18, $R$18,$Q$19,$R$19,$Q$20,$R$20,$Q$21,$R$21,$Q$22,$R$22,$Q$23,$R$23,$Q$24,$R$24), 0)} -> 0 | K17: =IFERROR(H17*(1-J17),0) -> 0 | L17: =IFERROR(K17*E17,0)/$L$5 -> 0 | M17: =IFERROR(K17*E17,0) -> 0 | N17: {=IFERROR(K17*(1+IFERROR(_xlfn.SWITCH(G17, $Q$10, $S$10, $Q$11, $S$11, $Q$12, $S$12, $Q$13, $S$13, $Q$14, $S$14, $Q$15, $S$15, $Q$16, $S$16, $Q$17, $S$17, $Q$18, $S$18,$Q$19,$S$19,$Q$20,$S$20,$Q$21,$S$21,$Q$22,$S$22,$Q$23,$S$23,$Q$24,$S$24), $S$10))*bp, 0)} -> 0 | O17: =IFERROR(N17*E17,0) -> 0 | Q17: 3rd Party | R17: 0 | S17: =isaas -> 0.1383 | U17: VAH | V17: ='Opp Name'!$E$6 -> 0 | W17: =SUMIF('Opp Name'!$F:$F,Table14[[#This Row],[Group]],'Opp Name'!$I:$I) -> 0 | X17: =W17/V17 -> #DIV/0! | Y17: =SUMIF('Opp Name'!$F:$F,Table14[[#This Row],[Group]],'Opp Name'!$M:$M) -> 0 | Z17: =Y17/V17 -> #DIV/0!
B18: 13 | I18: =H18*E18 -> 0 | J18: {=IFERROR(_xlfn.SWITCH(G18, $Q$10, $R$10, $Q$11, $R$11, $Q$12, $R$12, $Q$13, $R$13, $Q$14, $R$14, $Q$15, $R$15, $Q$16, $R$16, $Q$17, $R$17, $Q$18, $R$18,$Q$19,$R$19,$Q$20,$R$20,$Q$21,$R$21,$Q$22,$R$22,$Q$23,$R$23,$Q$24,$R$24), 0)} -> 0 | K18: =IFERROR(H18*(1-J18),0) -> 0 | L18: =IFERROR(K18*E18,0)/$L$5 -> 0 | M18: =IFERROR(K18*E18,0) -> 0 | N18: {=IFERROR(K18*(1+IFERROR(_xlfn.SWITCH(G18, $Q$10, $S$10, $Q$11, $S$11, $Q$12, $S$12, $Q$13, $S$13, $Q$14, $S$14, $Q$15, $S$15, $Q$16, $S$16, $Q$17, $S$17, $Q$18, $S$18,$Q$19,$S$19,$Q$20,$S$20,$Q$21,$S$21,$Q$22,$S$22,$Q$23,$S$23,$Q$24,$S$24), $S$10))*bp, 0)} -> 0 | O18: =IFERROR(N18*E18,0) -> 0 | Q18: Training and Onboarding | R18: 0 | S18: =iserv -> 0.0701 | U18: CRM | V18: ='Opp Name'!$E$6 -> 0 | W18: =SUMIF('Opp Name'!$F:$F,Table14[[#This Row],[Group]],'Opp Name'!$I:$I) -> 0 | X18: =W18/V18 -> #DIV/0! | Y18: =SUMIF('Opp Name'!$F:$F,Table14[[#This Row],[Group]],'Opp Name'!$M:$M) -> 0 | Z18: =Y18/V18 -> #DIV/0!
B19: 14 | I19: =H19*E19 -> 0 | J19: {=IFERROR(_xlfn.SWITCH(G19, $Q$10, $R$10, $Q$11, $R$11, $Q$12, $R$12, $Q$13, $R$13, $Q$14, $R$14, $Q$15, $R$15, $Q$16, $R$16, $Q$17, $R$17, $Q$18, $R$18,$Q$19,$R$19,$Q$20,$R$20,$Q$21,$R$21,$Q$22,$R$22,$Q$23,$R$23,$Q$24,$R$24), 0)} -> 0 | K19: =IFERROR(H19*(1-J19),0) -> 0 | L19: =IFERROR(K19*E19,0)/$L$5 -> 0 | M19: =IFERROR(K19*E19,0) -> 0 | N19: {=IFERROR(K19*(1+IFERROR(_xlfn.SWITCH(G19, $Q$10, $S$10, $Q$11, $S$11, $Q$12, $S$12, $Q$13, $S$13, $Q$14, $S$14, $Q$15, $S$15, $Q$16, $S$16, $Q$17, $S$17, $Q$18, $S$18,$Q$19,$S$19,$Q$20,$S$20,$Q$21,$S$21,$Q$22,$S$22,$Q$23,$S$23,$Q$24,$S$24), $S$10))*bp, 0)} -> 0 | O19: =IFERROR(N19*E19,0) -> 0 | Q19: Connectivity MRC | R19: 0 | S19: =iconn -> 0.11 | U19: Add-on | V19: ='Opp Name'!$E$6 -> 0 | W19: =SUMIF('Opp Name'!$F:$F,Table14[[#This Row],[Group]],'Opp Name'!$I:$I) -> 0 | X19: =W19/V19 -> #DIV/0! | Y19: =SUMIF('Opp Name'!$F:$F,Table14[[#This Row],[Group]],'Opp Name'!$M:$M) -> 0 | Z19: =Y19/V19 -> #DIV/0!
B20: 15 | I20: =H20*E20 -> 0 | J20: {=IFERROR(_xlfn.SWITCH(G20, $Q$10, $R$10, $Q$11, $R$11, $Q$12, $R$12, $Q$13, $R$13, $Q$14, $R$14, $Q$15, $R$15, $Q$16, $R$16, $Q$17, $R$17, $Q$18, $R$18,$Q$19,$R$19,$Q$20,$R$20,$Q$21,$R$21,$Q$22,$R$22,$Q$23,$R$23,$Q$24,$R$24), 0)} -> 0 | K20: =IFERROR(H20*(1-J20),0) -> 0 | L20: =IFERROR(K20*E20,0)/$L$5 -> 0 | M20: =IFERROR(K20*E20,0) -> 0 | N20: {=IFERROR(K20*(1+IFERROR(_xlfn.SWITCH(G20, $Q$10, $S$10, $Q$11, $S$11, $Q$12, $S$12, $Q$13, $S$13, $Q$14, $S$14, $Q$15, $S$15, $Q$16, $S$16, $Q$17, $S$17, $Q$18, $S$18,$Q$19,$S$19,$Q$20,$S$20,$Q$21,$S$21,$Q$22,$S$22,$Q$23,$S$23,$Q$24,$S$24), $S$10))*bp, 0)} -> 0 | O20: =IFERROR(N20*E20,0) -> 0 | Q20: Connectivity NRC | R20: 0 | S20: =iconn -> 0.11 | U20: Others | V20: ='Opp Name'!$E$6 -> 0 | W20: =SUMIF('Opp Name'!$F:$F,Table14[[#This Row],[Group]],'Opp Name'!$I:$I) -> 0 | X20: =W20/V20 -> #DIV/0! | Y20: =SUMIF('Opp Name'!$F:$F,Table14[[#This Row],[Group]],'Opp Name'!$M:$M) -> 0 | Z20: =Y20/V20 -> #DIV/0!
B21: 16 | I21: =H21*E21 -> 0 | J21: {=IFERROR(_xlfn.SWITCH(G21, $Q$10, $R$10, $Q$11, $R$11, $Q$12, $R$12, $Q$13, $R$13, $Q$14, $R$14, $Q$15, $R$15, $Q$16, $R$16, $Q$17, $R$17, $Q$18, $R$18,$Q$19,$R$19,$Q$20,$R$20,$Q$21,$R$21,$Q$22,$R$22,$Q$23,$R$23,$Q$24,$R$24), 0)} -> 0 | K21: =IFERROR(H21*(1-J21),0) -> 0 | L21: =IFERROR(K21*E21,0)/$L$5 -> 0 | M21: =IFERROR(K21*E21,0) -> 0 | N21: {=IFERROR(K21*(1+IFERROR(_xlfn.SWITCH(G21, $Q$10, $S$10, $Q$11, $S$11, $Q$12, $S$12, $Q$13, $S$13, $Q$14, $S$14, $Q$15, $S$15, $Q$16, $S$16, $Q$17, $S$17, $Q$18, $S$18,$Q$19,$S$19,$Q$20,$S$20,$Q$21,$S$21,$Q$22,$S$22,$Q$23,$S$23,$Q$24,$S$24), $S$10))*bp, 0)} -> 0 | O21: =IFERROR(N21*E21,0) -> 0 | Q21: Usage | R21: 0 | S21: =isaas -> 0.1383 | T21: #0C769E | V21: ='Opp Name'!$E$6 -> 0 | W21: =SUMIF('Opp Name'!$F:$F,Table14[[#This Row],[Group]],'Opp Name'!$I:$I) -> 0 | X21: =W21/V21 -> #DIV/0! | Y21: =SUMIF('Opp Name'!$F:$F,Table14[[#This Row],[Group]],'Opp Name'!$M:$M) -> 0 | Z21: =Y21/V21 -> #DIV/0!
B22: 17 | I22: =H22*E22 -> 0 | J22: {=IFERROR(_xlfn.SWITCH(G22, $Q$10, $R$10, $Q$11, $R$11, $Q$12, $R$12, $Q$13, $R$13, $Q$14, $R$14, $Q$15, $R$15, $Q$16, $R$16, $Q$17, $R$17, $Q$18, $R$18,$Q$19,$R$19,$Q$20,$R$20,$Q$21,$R$21,$Q$22,$R$22,$Q$23,$R$23,$Q$24,$R$24), 0)} -> 0 | K22: =IFERROR(H22*(1-J22),0) -> 0 | L22: =IFERROR(K22*E22,0)/$L$5 -> 0 | M22: =IFERROR(K22*E22,0) -> 0 | N22: {=IFERROR(K22*(1+IFERROR(_xlfn.SWITCH(G22, $Q$10, $S$10, $Q$11, $S$11, $Q$12, $S$12, $Q$13, $S$13, $Q$14, $S$14, $Q$15, $S$15, $Q$16, $S$16, $Q$17, $S$17, $Q$18, $S$18,$Q$19,$S$19,$Q$20,$S$20,$Q$21,$S$21,$Q$22,$S$22,$Q$23,$S$23,$Q$24,$S$24), $S$10))*bp, 0)} -> 0 | O22: =IFERROR(N22*E22,0) -> 0 | Q22: Schedule B | R22: 0 | S22: =isaas -> 0.1383 | T22: #92D050 | V22: ='Opp Name'!$E$6 -> 0 | W22: =SUMIF('Opp Name'!$F:$F,Table14[[#This Row],[Group]],'Opp Name'!$I:$I) -> 0 | X22: =W22/V22 -> #DIV/0! | Y22: =SUMIF('Opp Name'!$F:$F,Table14[[#This Row],[Group]],'Opp Name'!$M:$M) -> 0 | Z22: =Y22/V22 -> #DIV/0!
B23: 18 | I23: =H23*E23 -> 0 | J23: {=IFERROR(_xlfn.SWITCH(G23, $Q$10, $R$10, $Q$11, $R$11, $Q$12, $R$12, $Q$13, $R$13, $Q$14, $R$14, $Q$15, $R$15, $Q$16, $R$16, $Q$17, $R$17, $Q$18, $R$18,$Q$19,$R$19,$Q$20,$R$20,$Q$21,$R$21,$Q$22,$R$22,$Q$23,$R$23,$Q$24,$R$24), 0)} -> 0 | K23: =IFERROR(H23*(1-J23),0) -> 0 | L23: =IFERROR(K23*E23,0)/$L$5 -> 0 | M23: =IFERROR(K23*E23,0) -> 0 | N23: {=IFERROR(K23*(1+IFERROR(_xlfn.SWITCH(G23, $Q$10, $S$10, $Q$11, $S$11, $Q$12, $S$12, $Q$13, $S$13, $Q$14, $S$14, $Q$15, $S$15, $Q$16, $S$16, $Q$17, $S$17, $Q$18, $S$18,$Q$19,$S$19,$Q$20,$S$20,$Q$21,$S$21,$Q$22,$S$22,$Q$23,$S$23,$Q$24,$S$24), $S$10))*bp, 0)} -> 0 | O23: =IFERROR(N23*E23,0) -> 0 | Q23: Storage | R23: 0 | S23: =isaas -> 0.1383 | T23: #E49EDD | V23: ='Opp Name'!$E$6 -> 0 | W23: =SUMIF('Opp Name'!$F:$F,Table14[[#This Row],[Group]],'Opp Name'!$I:$I) -> 0 | X23: =W23/V23 -> #DIV/0! | Y23: =SUMIF('Opp Name'!$F:$F,Table14[[#This Row],[Group]],'Opp Name'!$M:$M) -> 0 | Z23: =Y23/V23 -> #DIV/0!
B24: 19 | I24: =H24*E24 -> 0 | J24: {=IFERROR(_xlfn.SWITCH(G24, $Q$10, $R$10, $Q$11, $R$11, $Q$12, $R$12, $Q$13, $R$13, $Q$14, $R$14, $Q$15, $R$15, $Q$16, $R$16, $Q$17, $R$17, $Q$18, $R$18,$Q$19,$R$19,$Q$20,$R$20,$Q$21,$R$21,$Q$22,$R$22,$Q$23,$R$23,$Q$24,$R$24), 0)} -> 0 | K24: =IFERROR(H24*(1-J24),0) -> 0 | L24: =IFERROR(K24*E24,0)/$L$5 -> 0 | M24: =IFERROR(K24*E24,0) -> 0 | N24: {=IFERROR(K24*(1+IFERROR(_xlfn.SWITCH(G24, $Q$10, $S$10, $Q$11, $S$11, $Q$12, $S$12, $Q$13, $S$13, $Q$14, $S$14, $Q$15, $S$15, $Q$16, $S$16, $Q$17, $S$17, $Q$18, $S$18,$Q$19,$S$19,$Q$20,$S$20,$Q$21,$S$21,$Q$22,$S$22,$Q$23,$S$23,$Q$24,$S$24), $S$10))*bp, 0)} -> 0 | O24: =IFERROR(N24*E24,0) -> 0 | R24: 0 | S24: =isaas -> 0.1383 | U24: Total | W24: =SUBTOTAL(109,Table14[List Price BRL]) -> 0 | Y24: =SUBTOTAL(109,Table14[Discounted Price BRL]) -> 0
B25: 20 | I25: =H25*E25 -> 0 | J25: {=IFERROR(_xlfn.SWITCH(G25, $Q$10, $R$10, $Q$11, $R$11, $Q$12, $R$12, $Q$13, $R$13, $Q$14, $R$14, $Q$15, $R$15, $Q$16, $R$16, $Q$17, $R$17, $Q$18, $R$18,$Q$19,$R$19,$Q$20,$R$20,$Q$21,$R$21,$Q$22,$R$22,$Q$23,$R$23,$Q$24,$R$24), 0)} -> 0 | K25: =IFERROR(H25*(1-J25),0) -> 0 | L25: =IFERROR(K25*E25,0)/$L$5 -> 0 | M25: =IFERROR(K25*E25,0) -> 0 | N25: {=IFERROR(K25*(1+IFERROR(_xlfn.SWITCH(G25, $Q$10, $S$10, $Q$11, $S$11, $Q$12, $S$12, $Q$13, $S$13, $Q$14, $S$14, $Q$15, $S$15, $Q$16, $S$16, $Q$17, $S$17, $Q$18, $S$18,$Q$19,$S$19,$Q$20,$S$20,$Q$21,$S$21,$Q$22,$S$22,$Q$23,$S$23,$Q$24,$S$24), $S$10))*bp, 0)} -> 0 | O25: =IFERROR(N25*E25,0) -> 0
B26: 21 | I26: =H26*E26 -> 0 | J26: {=IFERROR(_xlfn.SWITCH(G26, $Q$10, $R$10, $Q$11, $R$11, $Q$12, $R$12, $Q$13, $R$13, $Q$14, $R$14, $Q$15, $R$15, $Q$16, $R$16, $Q$17, $R$17, $Q$18, $R$18,$Q$19,$R$19,$Q$20,$R$20,$Q$21,$R$21,$Q$22,$R$22,$Q$23,$R$23,$Q$24,$R$24), 0)} -> 0 | K26: =IFERROR(H26*(1-J26),0) -> 0 | L26: =IFERROR(K26*E26,0)/$L$5 -> 0 | M26: =IFERROR(K26*E26,0) -> 0 | N26: {=IFERROR(K26*(1+IFERROR(_xlfn.SWITCH(G26, $Q$10, $S$10, $Q$11, $S$11, $Q$12, $S$12, $Q$13, $S$13, $Q$14, $S$14, $Q$15, $S$15, $Q$16, $S$16, $Q$17, $S$17, $Q$18, $S$18,$Q$19,$S$19,$Q$20,$S$20,$Q$21,$S$21,$Q$22,$S$22,$Q$23,$S$23,$Q$24,$S$24), $S$10))*bp, 0)} -> 0 | O26: =IFERROR(N26*E26,0) -> 0
I27: =SUM(I6:I26) -> 0 | L27: =SUM(L6:L26) -> 0 | M27: =SUM(M6:M26) -> 0 | O27: =SUM(O6:O26) -> 0
L28: =L27/E6 -> #DIV/0!
B29: SOFTWARE USAGE PRODUCTS | H29: PRICE LIST | J29: FOB NET PRICE | N29: SELL PRICE (WITH TAXES)
B30: # | C30: Product | D30: SKU | E30: Quantity | F30: Group | G30: Prod Category Discount | H30: Unit Partner Price | I30: Total Partner Price | J30: Additional Discount | K30: Unit Price (FOB) | L30: =$L$5 -> 5.8 | M30: FOB NET | N30: Unit Sell Price | O30: Total Sell Price
B31: 1 | I31: =H31*E31 -> 0 | J31: {=IFERROR(_xlfn.SWITCH(G31, $Q$10, $R$10, $Q$11, $R$11, $Q$12, $R$12, $Q$13, $R$13, $Q$14, $R$14, $Q$15, $R$15, $Q$16, $R$16, $Q$17, $R$17, $Q$18, $R$18,$Q$19,$R$19,$Q$20,$R$20,$Q$21,$R$21,$Q$22,$R$22,$Q$23,$R$23,$Q$24,$R$24), 0)} -> 0 | K31: =IFERROR(H31*(1-J31),0) -> 0 | L31: =IFERROR(K31*E31,0)/$L$5 -> 0 | M31: =IFERROR(K31*E31,0) -> 0 | N31: {=IFERROR(K31*(1+IFERROR(_xlfn.SWITCH(G31, $Q$10, $S$10, $Q$11, $S$11, $Q$12, $S$12, $Q$13, $S$13, $Q$14, $S$14, $Q$15, $S$15, $Q$16, $S$16, $Q$17, $S$17, $Q$18, $S$18,$Q$19,$S$19,$Q$20,$S$20,$Q$21,$S$21,$Q$22,$S$22,$Q$23,$S$23,$Q$24,$S$24), $S$10))*bp, 0)} -> 0 | O31: =IFERROR(N31*E31,0) -> 0
B32: 2 | I32: =H32*E32 -> 0 | J32: {=IFERROR(_xlfn.SWITCH(G32, $Q$10, $R$10, $Q$11, $R$11, $Q$12, $R$12, $Q$13, $R$13, $Q$14, $R$14, $Q$15, $R$15, $Q$16, $R$16, $Q$17, $R$17, $Q$18, $R$18,$Q$19,$R$19,$Q$20,$R$20,$Q$21,$R$21,$Q$22,$R$22,$Q$23,$R$23,$Q$24,$R$24), 0)} -> 0 | K32: =IFERROR(H32*(1-J32),0) -> 0 | L32: =IFERROR(K32*E32,0)/$L$5 -> 0 | M32: =IFERROR(K32*E32,0) -> 0 | N32: {=IFERROR(K32*(1+IFERROR(_xlfn.SWITCH(G32, $Q$10, $S$10, $Q$11, $S$11, $Q$12, $S$12, $Q$13, $S$13, $Q$14, $S$14, $Q$15, $S$15, $Q$16, $S$16, $Q$17, $S$17, $Q$18, $S$18,$Q$19,$S$19,$Q$20,$S$20,$Q$21,$S$21,$Q$22,$S$22,$Q$23,$S$23,$Q$24,$S$24), $S$10))*bp, 0)} -> 0 | O32: =IFERROR(N32*E32,0) -> 0
B33: 3 | I33: =H33*E33 -> 0 | J33: {=IFERROR(_xlfn.SWITCH(G33, $Q$10, $R$10, $Q$11, $R$11, $Q$12, $R$12, $Q$13, $R$13, $Q$14, $R$14, $Q$15, $R$15, $Q$16, $R$16, $Q$17, $R$17, $Q$18, $R$18,$Q$19,$R$19,$Q$20,$R$20,$Q$21,$R$21,$Q$22,$R$22,$Q$23,$R$23,$Q$24,$R$24), 0)} -> 0 | K33: =IFERROR(H33*(1-J33),0) -> 0 | L33: =IFERROR(K33*E33,0)/$L$5 -> 0 | M33: =IFERROR(K33*E33,0) -> 0 | N33: {=IFERROR(K33*(1+IFERROR(_xlfn.SWITCH(G33, $Q$10, $S$10, $Q$11, $S$11, $Q$12, $S$12, $Q$13, $S$13, $Q$14, $S$14, $Q$15, $S$15, $Q$16, $S$16, $Q$17, $S$17, $Q$18, $S$18,$Q$19,$S$19,$Q$20,$S$20,$Q$21,$S$21,$Q$22,$S$22,$Q$23,$S$23,$Q$24,$S$24), $S$10))*bp, 0)} -> 0 | O33: =IFERROR(N33*E33,0) -> 0
B34: 4 | I34: =H34*E34 -> 0 | J34: {=IFERROR(_xlfn.SWITCH(G34, $Q$10, $R$10, $Q$11, $R$11, $Q$12, $R$12, $Q$13, $R$13, $Q$14, $R$14, $Q$15, $R$15, $Q$16, $R$16, $Q$17, $R$17, $Q$18, $R$18,$Q$19,$R$19,$Q$20,$R$20,$Q$21,$R$21,$Q$22,$R$22,$Q$23,$R$23,$Q$24,$R$24), 0)} -> 0 | K34: =IFERROR(H34*(1-J34),0) -> 0 | L34: =IFERROR(K34*E34,0)/$L$5 -> 0 | M34: =IFERROR(K34*E34,0) -> 0 | N34: {=IFERROR(K34*(1+IFERROR(_xlfn.SWITCH(G34, $Q$10, $S$10, $Q$11, $S$11, $Q$12, $S$12, $Q$13, $S$13, $Q$14, $S$14, $Q$15, $S$15, $Q$16, $S$16, $Q$17, $S$17, $Q$18, $S$18,$Q$19,$S$19,$Q$20,$S$20,$Q$21,$S$21,$Q$22,$S$22,$Q$23,$S$23,$Q$24,$S$24), $S$10))*bp, 0)} -> 0 | O34: =IFERROR(N34*E34,0) -> 0
B35: 5 | I35: =H35*E35 -> 0 | J35: {=IFERROR(_xlfn.SWITCH(G35, $Q$10, $R$10, $Q$11, $R$11, $Q$12, $R$12, $Q$13, $R$13, $Q$14, $R$14, $Q$15, $R$15, $Q$16, $R$16, $Q$17, $R$17, $Q$18, $R$18,$Q$19,$R$19,$Q$20,$R$20,$Q$21,$R$21,$Q$22,$R$22,$Q$23,$R$23,$Q$24,$R$24), 0)} -> 0 | K35: =IFERROR(H35*(1-J35),0) -> 0 | L35: =IFERROR(K35*E35,0)/$L$5 -> 0 | M35: =IFERROR(K35*E35,0) -> 0 | N35: {=IFERROR(K35*(1+IFERROR(_xlfn.SWITCH(G35, $Q$10, $S$10, $Q$11, $S$11, $Q$12, $S$12, $Q$13, $S$13, $Q$14, $S$14, $Q$15, $S$15, $Q$16, $S$16, $Q$17, $S$17, $Q$18, $S$18,$Q$19,$S$19,$Q$20,$S$20,$Q$21,$S$21,$Q$22,$S$22,$Q$23,$S$23,$Q$24,$S$24), $S$10))*bp, 0)} -> 0 | O35: =IFERROR(N35*E35,0) -> 0
B36: 6 | I36: =H36*E36 -> 0 | J36: {=IFERROR(_xlfn.SWITCH(G36, $Q$10, $R$10, $Q$11, $R$11, $Q$12, $R$12, $Q$13, $R$13, $Q$14, $R$14, $Q$15, $R$15, $Q$16, $R$16, $Q$17, $R$17, $Q$18, $R$18,$Q$19,$R$19,$Q$20,$R$20,$Q$21,$R$21,$Q$22,$R$22,$Q$23,$R$23,$Q$24,$R$24), 0)} -> 0 | K36: =IFERROR(H36*(1-J36),0) -> 0 | L36: =IFERROR(K36*E36,0)/$L$5 -> 0 | M36: =IFERROR(K36*E36,0) -> 0 | N36: {=IFERROR(K36*(1+IFERROR(_xlfn.SWITCH(G36, $Q$10, $S$10, $Q$11, $S$11, $Q$12, $S$12, $Q$13, $S$13, $Q$14, $S$14, $Q$15, $S$15, $Q$16, $S$16, $Q$17, $S$17, $Q$18, $S$18,$Q$19,$S$19,$Q$20,$S$20,$Q$21,$S$21,$Q$22,$S$22,$Q$23,$S$23,$Q$24,$S$24), $S$10))*bp, 0)} -> 0 | O36: =IFERROR(N36*E36,0) -> 0
B37: 7 | I37: =H37*E37 -> 0 | J37: {=IFERROR(_xlfn.SWITCH(G37, $Q$10, $R$10, $Q$11, $R$11, $Q$12, $R$12, $Q$13, $R$13, $Q$14, $R$14, $Q$15, $R$15, $Q$16, $R$16, $Q$17, $R$17, $Q$18, $R$18,$Q$19,$R$19,$Q$20,$R$20,$Q$21,$R$21,$Q$22,$R$22,$Q$23,$R$23,$Q$24,$R$24), 0)} -> 0 | K37: =IFERROR(H37*(1-J37),0) -> 0 | L37: =IFERROR(K37*E37,0)/$L$5 -> 0 | M37: =IFERROR(K37*E37,0) -> 0 | N37: {=IFERROR(K37*(1+IFERROR(_xlfn.SWITCH(G37, $Q$10, $S$10, $Q$11, $S$11, $Q$12, $S$12, $Q$13, $S$13, $Q$14, $S$14, $Q$15, $S$15, $Q$16, $S$16, $Q$17, $S$17, $Q$18, $S$18,$Q$19,$S$19,$Q$20,$S$20,$Q$21,$S$21,$Q$22,$S$22,$Q$23,$S$23,$Q$24,$S$24), $S$10))*bp, 0)} -> 0 | O37: =IFERROR(N37*E37,0) -> 0
B38: 8 | I38: =H38*E38 -> 0 | J38: {=IFERROR(_xlfn.SWITCH(G38, $Q$10, $R$10, $Q$11, $R$11, $Q$12, $R$12, $Q$13, $R$13, $Q$14, $R$14, $Q$15, $R$15, $Q$16, $R$16, $Q$17, $R$17, $Q$18, $R$18,$Q$19,$R$19,$Q$20,$R$20,$Q$21,$R$21,$Q$22,$R$22,$Q$23,$R$23,$Q$24,$R$24), 0)} -> 0 | K38: =IFERROR(H38*(1-J38),0) -> 0 | L38: =IFERROR(K38*E38,0)/$L$5 -> 0 | M38: =IFERROR(K38*E38,0) -> 0 | N38: {=IFERROR(K38*(1+IFERROR(_xlfn.SWITCH(G38, $Q$10, $S$10, $Q$11, $S$11, $Q$12, $S$12, $Q$13, $S$13, $Q$14, $S$14, $Q$15, $S$15, $Q$16, $S$16, $Q$17, $S$17, $Q$18, $S$18,$Q$19,$S$19,$Q$20,$S$20,$Q$21,$S$21,$Q$22,$S$22,$Q$23,$S$23,$Q$24,$S$24), $S$10))*bp, 0)} -> 0 | O38: =IFERROR(N38*E38,0) -> 0
B39: 9 | I39: =H39*E39 -> 0 | J39: {=IFERROR(_xlfn.SWITCH(G39, $Q$10, $R$10, $Q$11, $R$11, $Q$12, $R$12, $Q$13, $R$13, $Q$14, $R$14, $Q$15, $R$15, $Q$16, $R$16, $Q$17, $R$17, $Q$18, $R$18,$Q$19,$R$19,$Q$20,$R$20,$Q$21,$R$21,$Q$22,$R$22,$Q$23,$R$23,$Q$24,$R$24), 0)} -> 0 | K39: =IFERROR(H39*(1-J39),0) -> 0 | L39: =IFERROR(K39*E39,0)/$L$5 -> 0 | M39: =IFERROR(K39*E39,0) -> 0 | N39: {=IFERROR(K39*(1+IFERROR(_xlfn.SWITCH(G39, $Q$10, $S$10, $Q$11, $S$11, $Q$12, $S$12, $Q$13, $S$13, $Q$14, $S$14, $Q$15, $S$15, $Q$16, $S$16, $Q$17, $S$17, $Q$18, $S$18,$Q$19,$S$19,$Q$20,$S$20,$Q$21,$S$21,$Q$22,$S$22,$Q$23,$S$23,$Q$24,$S$24), $S$10))*bp, 0)} -> 0 | O39: =IFERROR(N39*E39,0) -> 0
B40: 10 | I40: =H40*E40 -> 0 | J40: {=IFERROR(_xlfn.SWITCH(G40, $Q$10, $R$10, $Q$11, $R$11, $Q$12, $R$12, $Q$13, $R$13, $Q$14, $R$14, $Q$15, $R$15, $Q$16, $R$16, $Q$17, $R$17, $Q$18, $R$18,$Q$19,$R$19,$Q$20,$R$20,$Q$21,$R$21,$Q$22,$R$22,$Q$23,$R$23,$Q$24,$R$24), 0)} -> 0 | K40: =IFERROR(H40*(1-J40),0) -> 0 | L40: =IFERROR(K40*E40,0)/$L$5 -> 0 | M40: =IFERROR(K40*E40,0) -> 0 | N40: {=IFERROR(K40*(1+IFERROR(_xlfn.SWITCH(G40, $Q$10, $S$10, $Q$11, $S$11, $Q$12, $S$12, $Q$13, $S$13, $Q$14, $S$14, $Q$15, $S$15, $Q$16, $S$16, $Q$17, $S$17, $Q$18, $S$18,$Q$19,$S$19,$Q$20,$S$20,$Q$21,$S$21,$Q$22,$S$22,$Q$23,$S$23,$Q$24,$S$24), $S$10))*bp, 0)} -> 0 | O40: =IFERROR(N40*E40,0) -> 0
B41: 11 | I41: =H41*E41 -> 0 | J41: {=IFERROR(_xlfn.SWITCH(G41, $Q$10, $R$10, $Q$11, $R$11, $Q$12, $R$12, $Q$13, $R$13, $Q$14, $R$14, $Q$15, $R$15, $Q$16, $R$16, $Q$17, $R$17, $Q$18, $R$18,$Q$19,$R$19,$Q$20,$R$20,$Q$21,$R$21,$Q$22,$R$22,$Q$23,$R$23,$Q$24,$R$24), 0)} -> 0 | K41: =IFERROR(H41*(1-J41),0) -> 0 | L41: =IFERROR(K41*E41,0)/$L$5 -> 0 | M41: =IFERROR(K41*E41,0) -> 0 | N41: {=IFERROR(K41*(1+IFERROR(_xlfn.SWITCH(G41, $Q$10, $S$10, $Q$11, $S$11, $Q$12, $S$12, $Q$13, $S$13, $Q$14, $S$14, $Q$15, $S$15, $Q$16, $S$16, $Q$17, $S$17, $Q$18, $S$18,$Q$19,$S$19,$Q$20,$S$20,$Q$21,$S$21,$Q$22,$S$22,$Q$23,$S$23,$Q$24,$S$24), $S$10))*bp, 0)} -> 0 | O41: =IFERROR(N41*E41,0) -> 0
B42: 12 | I42: =H42*E42 -> 0 | J42: {=IFERROR(_xlfn.SWITCH(G42, $Q$10, $R$10, $Q$11, $R$11, $Q$12, $R$12, $Q$13, $R$13, $Q$14, $R$14, $Q$15, $R$15, $Q$16, $R$16, $Q$17, $R$17, $Q$18, $R$18,$Q$19,$R$19,$Q$20,$R$20,$Q$21,$R$21,$Q$22,$R$22,$Q$23,$R$23,$Q$24,$R$24), 0)} -> 0 | K42: =IFERROR(H42*(1-J42),0) -> 0 | L42: =IFERROR(K42*E42,0)/$L$5 -> 0 | M42: =IFERROR(K42*E42,0) -> 0 | N42: {=IFERROR(K42*(1+IFERROR(_xlfn.SWITCH(G42, $Q$10, $S$10, $Q$11, $S$11, $Q$12, $S$12, $Q$13, $S$13, $Q$14, $S$14, $Q$15, $S$15, $Q$16, $S$16, $Q$17, $S$17, $Q$18, $S$18,$Q$19,$S$19,$Q$20,$S$20,$Q$21,$S$21,$Q$22,$S$22,$Q$23,$S$23,$Q$24,$S$24), $S$10))*bp, 0)} -> 0 | O42: =IFERROR(N42*E42,0) -> 0
...

Sheet Opportunity_Name USD
B2: CXONE DIGITAL AGENT - 36 Meses
B4: SOFTWARE MRC PRODUCTS | H4: PRICE LIST | J4: FOB NET PRICE | N4: SELL PRICE (WITH TAXES) | Q4: Imposto de Licença | R4: 0.1383
B5: # | C5: Product | D5: SKU | E5: Quantity | F5: Group | G5: Prod Category Discount | H5: Unit Partner Price | I5: Total Partner Price | J5: Additional Discount | K5: Unit Price (FOB) | L5: 1 | M5: FOB NET | N5: Unit Sell Price | O5: Total Sell Price | Q5: Imposto de Serviço | R5: 0.0701
B6: 1 | I6: =H6*E6 -> 0 | J6: {=IFERROR(_xlfn.SWITCH(G6, $Q$10, $R$10, $Q$11, $R$11, $Q$12, $R$12, $Q$13, $R$13, $Q$14, $R$14, $Q$15, $R$15, $Q$16, $R$16, $Q$17, $R$17, $Q$18, $R$18,$Q$19,$R$19,$Q$20,$R$20,$Q$21,$R$21,$Q$22,$R$22,$Q$23,$R$23,$Q$24,$R$24), 0)} -> 0 | K6: =IFERROR(H6*(1-J6),0) -> 0 | L6: =IFERROR(K6*E6,0)/$L$5 -> 0 | M6: =IFERROR(K6*E6,0) -> 0 | N6: {=IFERROR(K6*(1+IFERROR(_xlfn.SWITCH(G6, $Q$10, $S$10, $Q$11, $S$11, $Q$12, $S$12, $Q$13, $S$13, $Q$14, $S$14, $Q$15, $S$15, $Q$16, $S$16, $Q$17, $S$17, $Q$18, $S$18,$Q$19,$S$19,$Q$20,$S$20,$Q$21,$S$21,$Q$22,$S$22,$Q$23,$S$23,$Q$24,$S$24), $S$10))*bp, 0)} -> 0 | O6: =IFERROR(N6*E6,0) -> 0 | Q6: Imposto Conn MPLS | R6: 0.11
B7: 2 | I7: =H7*E7 -> 0 | J7: {=IFERROR(_xlfn.SWITCH(G7, $Q$10, $R$10, $Q$11, $R$11, $Q$12, $R$12, $Q$13, $R$13, $Q$14, $R$14, $Q$15, $R$15, $Q$16, $R$16, $Q$17, $R$17, $Q$18, $R$18,$Q$19,$R$19,$Q$20,$R$20,$Q$21,$R$21,$Q$22,$R$22,$Q$23,$R$23,$Q$24,$R$24), 0)} -> 0 | K7: =IFERROR(H7*(1-J7),0) -> 0 | L7: =IFERROR(K7*E7,0)/$L$5 -> 0 | M7: =IFERROR(K7*E7,0) -> 0 | N7: {=IFERROR(K7*(1+IFERROR(_xlfn.SWITCH(G7, $Q$10, $S$10, $Q$11, $S$11, $Q$12, $S$12, $Q$13, $S$13, $Q$14, $S$14, $Q$15, $S$15, $Q$16, $S$16, $Q$17, $S$17, $Q$18, $S$18,$Q$19,$S$19,$Q$20,$S$20,$Q$21,$S$21,$Q$22,$S$22,$Q$23,$S$23,$Q$24,$S$24), $S$10))*bp, 0)} -> 0 | O7: =IFERROR(N7*E7,0) -> 0 | Q7: BP Factor | R7: 1
B8: 3 | I8: =H8*E8 -> 0 | J8: {=IFERROR(_xlfn.SWITCH(G8, $Q$10, $R$10, $Q$11, $R$11, $Q$12, $R$12, $Q$13, $R$13, $Q$14, $R$14, $Q$15, $R$15, $Q$16, $R$16, $Q$17, $R$17, $Q$18, $R$18,$Q$19,$R$19,$Q$20,$R$20,$Q$21,$R$21,$Q$22,$R$22,$Q$23,$R$23,$Q$24,$R$24), 0)} -> 0 | K8: =IFERROR(H8*(1-J8),0) -> 0 | L8: =IFERROR(K8*E8,0)/$L$5 -> 0 | M8: =IFERROR(K8*E8,0) -> 0 | N8: {=IFERROR(K8*(1+IFERROR(_xlfn.SWITCH(G8, $Q$10, $S$10, $Q$11, $S$11, $Q$12, $S$12, $Q$13, $S$13, $Q$14, $S$14, $Q$15, $S$15, $Q$16, $S$16, $Q$17, $S$17, $Q$18, $S$18,$Q$19,$S$19,$Q$20,$S$20,$Q$21,$S$21,$Q$22,$S$22,$Q$23,$S$23,$Q$24,$S$24), $S$10))*bp, 0)} -> 0 | O8: =IFERROR(N8*E8,0) -> 0
B9: 4 | I9: =H9*E9 -> 0 | J9: {=IFERROR(_xlfn.SWITCH(G9, $Q$10, $R$10, $Q$11, $R$11, $Q$12, $R$12, $Q$13, $R$13, $Q$14, $R$14, $Q$15, $R$15, $Q$16, $R$16, $Q$17, $R$17, $Q$18, $R$18,$Q$19,$R$19,$Q$20,$R$20,$Q$21,$R$21,$Q$22,$R$22,$Q$23,$R$23,$Q$24,$R$24), 0)} -> 0 | K9: =IFERROR(H9*(1-J9),0) -> 0 | L9: =IFERROR(K9*E9,0)/$L$5 -> 0 | M9: =IFERROR(K9*E9,0) -> 0 | N9: {=IFERROR(K9*(1+IFERROR(_xlfn.SWITCH(G9, $Q$10, $S$10, $Q$11, $S$11, $Q$12, $S$12, $Q$13, $S$13, $Q$14, $S$14, $Q$15, $S$15, $Q$16, $S$16, $Q$17, $S$17, $Q$18, $S$18,$Q$19,$S$19,$Q$20,$S$20,$Q$21,$S$21,$Q$22,$S$22,$Q$23,$S$23,$Q$24,$S$24), $S$10))*bp, 0)} -> 0 | O9: =IFERROR(N9*E9,0) -> 0 | R9: Discount | S9: Local Taxes | U9: Group | V9: Quantity | W9: List Price BRL | X9: Price per license BRL | Y9: Discounted Price BRL | Z9: Discounted Price per license BRL
B10: 5 | I10: =H10*E10 -> 0 | J10: {=IFERROR(_xlfn.SWITCH(G10, $Q$10, $R$10, $Q$11, $R$11, $Q$12, $R$12, $Q$13, $R$13, $Q$14, $R$14, $Q$15, $R$15, $Q$16, $R$16, $Q$17, $R$17, $Q$18, $R$18,$Q$19,$R$19,$Q$20,$R$20,$Q$21,$R$21,$Q$22,$R$22,$Q$23,$R$23,$Q$24,$R$24), 0)} -> 0 | K10: =IFERROR(H10*(1-J10),0) -> 0 | L10: =IFERROR(K10*E10,0)/$L$5 -> 0 | M10: =IFERROR(K10*E10,0) -> 0 | N10: {=IFERROR(K10*(1+IFERROR(_xlfn.SWITCH(G10, $Q$10, $S$10, $Q$11, $S$11, $Q$12, $S$12, $Q$13, $S$13, $Q$14, $S$14, $Q$15, $S$15, $Q$16, $S$16, $Q$17, $S$17, $Q$18, $S$18,$Q$19,$S$19,$Q$20,$S$20,$Q$21,$S$21,$Q$22,$S$22,$Q$23,$S$23,$Q$24,$S$24), $S$10))*bp, 0)} -> 0 | O10: =IFERROR(N10*E10,0) -> 0 | Q10: Bundle | R10: 0 | S10: =isaas -> 0.1383 | U10: Bundle | V10: ='Opportunity_Name USD'!$E$6 -> 0 | W10: =SUMIF('Opp Name'!$F:$F,Table142[[#This Row],[Group]],'Opp Name'!$I:$I) -> 0 | X10: =W10/V10 -> #DIV/0! | Y10: =SUMIF('Opp Name'!$F:$F,Table142[[#This Row],[Group]],'Opp Name'!$M:$M) -> 0 | Z10: =Y10/V10 -> #DIV/0!
B11: 6 | I11: =H11*E11 -> 0 | J11: {=IFERROR(_xlfn.SWITCH(G11, $Q$10, $R$10, $Q$11, $R$11, $Q$12, $R$12, $Q$13, $R$13, $Q$14, $R$14, $Q$15, $R$15, $Q$16, $R$16, $Q$17, $R$17, $Q$18, $R$18,$Q$19,$R$19,$Q$20,$R$20,$Q$21,$R$21,$Q$22,$R$22,$Q$23,$R$23,$Q$24,$R$24), 0)} -> 0 | K11: =IFERROR(H11*(1-J11),0) -> 0 | L11: =IFERROR(K11*E11,0)/$L$5 -> 0 | M11: =IFERROR(K11*E11,0) -> 0 | N11: {=IFERROR(K11*(1+IFERROR(_xlfn.SWITCH(G11, $Q$10, $S$10, $Q$11, $S$11, $Q$12, $S$12, $Q$13, $S$13, $Q$14, $S$14, $Q$15, $S$15, $Q$16, $S$16, $Q$17, $S$17, $Q$18, $S$18,$Q$19,$S$19,$Q$20,$S$20,$Q$21,$S$21,$Q$22,$S$22,$Q$23,$S$23,$Q$24,$S$24), $S$10))*bp, 0)} -> 0 | O11: =IFERROR(N11*E11,0) -> 0 | Q11: Integrated SW | R11: 0 | S11: =isaas -> 0.1383 | U11: Success Package | V11: ='Opportunity_Name USD'!$E$6 -> 0 | W11: =SUMIF('Opp Name'!$F:$F,Table142[[#This Row],[Group]],'Opp Name'!$I:$I) -> 0 | X11: =W11/V11 -> #DIV/0! | Y11: =SUMIF('Opp Name'!$F:$F,Table142[[#This Row],[Group]],'Opp Name'!$M:$M) -> 0 | Z11: =Y11/V11 -> #DIV/0!
B12: 7 | I12: =H12*E12 -> 0 | J12: {=IFERROR(_xlfn.SWITCH(G12, $Q$10, $R$10, $Q$11, $R$11, $Q$12, $R$12, $Q$13, $R$13, $Q$14, $R$14, $Q$15, $R$15, $Q$16, $R$16, $Q$17, $R$17, $Q$18, $R$18,$Q$19,$R$19,$Q$20,$R$20,$Q$21,$R$21,$Q$22,$R$22,$Q$23,$R$23,$Q$24,$R$24), 0)} -> 0 | K12: =IFERROR(H12*(1-J12),0) -> 0 | L12: =IFERROR(K12*E12,0)/$L$5 -> 0 | M12: =IFERROR(K12*E12,0) -> 0 | N12: {=IFERROR(K12*(1+IFERROR(_xlfn.SWITCH(G12, $Q$10, $S$10, $Q$11, $S$11, $Q$12, $S$12, $Q$13, $S$13, $Q$14, $S$14, $Q$15, $S$15, $Q$16, $S$16, $Q$17, $S$17, $Q$18, $S$18,$Q$19,$S$19,$Q$20,$S$20,$Q$21,$S$21,$Q$22,$S$22,$Q$23,$S$23,$Q$24,$S$24), $S$10))*bp, 0)} -> 0 | O12: =IFERROR(N12*E12,0) -> 0 | Q12: CXone SW | R12: 0 | S12: =isaas -> 0.1383 | U12: Video/Co-browse | V12: ='Opportunity_Name USD'!$E$6 -> 0 | W12: =SUMIF('Opp Name'!$F:$F,Table142[[#This Row],[Group]],'Opp Name'!$I:$I) -> 0 | X12: =W12/V12 -> #DIV/0! | Y12: =SUMIF('Opp Name'!$F:$F,Table142[[#This Row],[Group]],'Opp Name'!$M:$M) -> 0 | Z12: =Y12/V12 -> #DIV/0!
B13: 8 | I13: =H13*E13 -> 0 | J13: {=IFERROR(_xlfn.SWITCH(G13, $Q$10, $R$10, $Q$11, $R$11, $Q$12, $R$12, $Q$13, $R$13, $Q$14, $R$14, $Q$15, $R$15, $Q$16, $R$16, $Q$17, $R$17, $Q$18, $R$18,$Q$19,$R$19,$Q$20,$R$20,$Q$21,$R$21,$Q$22,$R$22,$Q$23,$R$23,$Q$24,$R$24), 0)} -> 0 | K13: =IFERROR(H13*(1-J13),0) -> 0 | L13: =IFERROR(K13*E13,0)/$L$5 -> 0 | M13: =IFERROR(K13*E13,0) -> 0 | N13: {=IFERROR(K13*(1+IFERROR(_xlfn.SWITCH(G13, $Q$10, $S$10, $Q$11, $S$11, $Q$12, $S$12, $Q$13, $S$13, $Q$14, $S$14, $Q$15, $S$15, $Q$16, $S$16, $Q$17, $S$17, $Q$18, $S$18,$Q$19,$S$19,$Q$20,$S$20,$Q$21,$S$21,$Q$22,$S$22,$Q$23,$S$23,$Q$24,$S$24), $S$10))*bp, 0)} -> 0 | O13: =IFERROR(N13*E13,0) -> 0 | Q13: Services | R13: 0 | S13: =iserv -> 0.0701 | U13: Dialer | V13: ='Opportunity_Name USD'!$E$6 -> 0 | W13: =SUMIF('Opp Name'!$F:$F,Table142[[#This Row],[Group]],'Opp Name'!$I:$I) -> 0 | X13: =W13/V13 -> #DIV/0! | Y13: =SUMIF('Opp Name'!$F:$F,Table142[[#This Row],[Group]],'Opp Name'!$M:$M) -> 0 | Z13: =Y13/V13 -> #DIV/0!
B14: 9 | I14: =H14*E14 -> 0 | J14: {=IFERROR(_xlfn.SWITCH(G14, $Q$10, $R$10, $Q$11, $R$11, $Q$12, $R$12, $Q$13, $R$13, $Q$14, $R$14, $Q$15, $R$15, $Q$16, $R$16, $Q$17, $R$17, $Q$18, $R$18,$Q$19,$R$19,$Q$20,$R$20,$Q$21,$R$21,$Q$22,$R$22,$Q$23,$R$23,$Q$24,$R$24), 0)} -> 0 | K14: =IFERROR(H14*(1-J14),0) -> 0 | L14: =IFERROR(K14*E14,0)/$L$5 -> 0 | M14: =IFERROR(K14*E14,0) -> 0 | N14: {=IFERROR(K14*(1+IFERROR(_xlfn.SWITCH(G14, $Q$10, $S$10, $Q$11, $S$11, $Q$12, $S$12, $Q$13, $S$13, $Q$14, $S$14, $Q$15, $S$15, $Q$16, $S$16, $Q$17, $S$17, $Q$18, $S$18,$Q$19,$S$19,$Q$20,$S$20,$Q$21,$S$21,$Q$22,$S$22,$Q$23,$S$23,$Q$24,$S$24), $S$10))*bp, 0)} -> 0 | O14: =IFERROR(N14*E14,0) -> 0 | Q14: Support | R14: 0 | S14: =isaas -> 0.1383 | U14: WFM IEX | V14: ='Opportunity_Name USD'!$E$6 -> 0 | W14: =SUMIF('Opp Name'!$F:$F,Table142[[#This Row],[Group]],'Opp Name'!$I:$I) -> 0 | X14: =W14/V14 -> #DIV/0! | Y14: =SUMIF('Opp Name'!$F:$F,Table142[[#This Row],[Group]],'Opp Name'!$M:$M) -> 0 | Z14: =Y14/V14 -> #DIV/0!
B15: 10 | I15: =H15*E15 -> 0 | J15: {=IFERROR(_xlfn.SWITCH(G15, $Q$10, $R$10, $Q$11, $R$11, $Q$12, $R$12, $Q$13, $R$13, $Q$14, $R$14, $Q$15, $R$15, $Q$16, $R$16, $Q$17, $R$17, $Q$18, $R$18,$Q$19,$R$19,$Q$20,$R$20,$Q$21,$R$21,$Q$22,$R$22,$Q$23,$R$23,$Q$24,$R$24), 0)} -> 0 | K15: =IFERROR(H15*(1-J15),0) -> 0 | L15: =IFERROR(K15*E15,0)/$L$5 -> 0 | M15: =IFERROR(K15*E15,0) -> 0 | N15: {=IFERROR(K15*(1+IFERROR(_xlfn.SWITCH(G15, $Q$10, $S$10, $Q$11, $S$11, $Q$12, $S$12, $Q$13, $S$13, $Q$14, $S$14, $Q$15, $S$15, $Q$16, $S$16, $Q$17, $S$17, $Q$18, $S$18,$Q$19,$S$19,$Q$20,$S$20,$Q$21,$S$21,$Q$22,$S$22,$Q$23,$S$23,$Q$24,$S$24), $S$10))*bp, 0)} -> 0 | O15: =IFERROR(N15*E15,0) -> 0 | Q15: Success Package | R15: 0 | S15: =isaas -> 0.1383 | U15: Knowledge | V15: ='Opportunity_Name USD'!$E$6 -> 0 | W15: =SUMIF('Opp Name'!$F:$F,Table142[[#This Row],[Group]],'Opp Name'!$I:$I) -> 0 | X15: =W15/V15 -> #DIV/0! | Y15: =SUMIF('Opp Name'!$F:$F,Table142[[#This Row],[Group]],'Opp Name'!$M:$M) -> 0 | Z15: =Y15/V15 -> #DIV/0!
B16: 11 | I16: =H16*E16 -> 0 | J16: {=IFERROR(_xlfn.SWITCH(G16, $Q$10, $R$10, $Q$11, $R$11, $Q$12, $R$12, $Q$13, $R$13, $Q$14, $R$14, $Q$15, $R$15, $Q$16, $R$16, $Q$17, $R$17, $Q$18, $R$18,$Q$19,$R$19,$Q$20,$R$20,$Q$21,$R$21,$Q$22,$R$22,$Q$23,$R$23,$Q$24,$R$24), 0)} -> 0 | K16: =IFERROR(H16*(1-J16),0) -> 0 | L16: =IFERROR(K16*E16,0)/$L$5 -> 0 | M16: =IFERROR(K16*E16,0) -> 0 | N16: {=IFERROR(K16*(1+IFERROR(_xlfn.SWITCH(G16, $Q$10, $S$10, $Q$11, $S$11, $Q$12, $S$12, $Q$13, $S$13, $Q$14, $S$14, $Q$15, $S$15, $Q$16, $S$16, $Q$17, $S$17, $Q$18, $S$18,$Q$19,$S$19,$Q$20,$S$20,$Q$21,$S$21,$Q$22,$S$22,$Q$23,$S$23,$Q$24,$S$24), $S$10))*bp, 0)} -> 0 | O16: =IFERROR(N16*E16,0) -> 0 | Q16: Others | R16: 0 | S16: =isaas -> 0.1383 | U16: Gamification | V16: ='Opportunity_Name USD'!$E$6 -> 0 | W16: =SUMIF('Opp Name'!$F:$F,Table142[[#This Row],[Group]],'Opp Name'!$I:$I) -> 0 | X16: =W16/V16 -> #DIV/0! | Y16: =SUMIF('Opp Name'!$F:$F,Table142[[#This Row],[Group]],'Opp Name'!$M:$M) -> 0 | Z16: =Y16/V16 -> #DIV/0!
B17: 12 | I17: =H17*E17 -> 0 | J17: {=IFERROR(_xlfn.SWITCH(G17, $Q$10, $R$10, $Q$11, $R$11, $Q$12, $R$12, $Q$13, $R$13, $Q$14, $R$14, $Q$15, $R$15, $Q$16, $R$16, $Q$17, $R$17, $Q$18, $R$18,$Q$19,$R$19,$Q$20,$R$20,$Q$21,$R$21,$Q$22,$R$22,$Q$23,$R$23,$Q$24,$R$24), 0)} -> 0 | K17: =IFERROR(H17*(1-J17),0) -> 0 | L17: =IFERROR(K17*E17,0)/$L$5 -> 0 | M17: =IFERROR(K17*E17,0) -> 0 | N17: {=IFERROR(K17*(1+IFERROR(_xlfn.SWITCH(G17, $Q$10, $S$10, $Q$11, $S$11, $Q$12, $S$12, $Q$13, $S$13, $Q$14, $S$14, $Q$15, $S$15, $Q$16, $S$16, $Q$17, $S$17, $Q$18, $S$18,$Q$19,$S$19,$Q$20,$S$20,$Q$21,$S$21,$Q$22,$S$22,$Q$23,$S$23,$Q$24,$S$24), $S$10))*bp, 0)} -> 0 | O17: =IFERROR(N17*E17,0) -> 0 | Q17: 3rd Party | R17: 0 | S17: =isaas -> 0.1383 | U17: VAH | V17: ='Opportunity_Name USD'!$E$6 -> 0 | W17: =SUMIF('Opp Name'!$F:$F,Table142[[#This Row],[Group]],'Opp Name'!$I:$I) -> 0 | X17: =W17/V17 -> #DIV/0! | Y17: =SUMIF('Opp Name'!$F:$F,Table142[[#This Row],[Group]],'Opp Name'!$M:$M) -> 0 | Z17: =Y17/V17 -> #DIV/0!
B18: 13 | I18: =H18*E18 -> 0 | J18: {=IFERROR(_xlfn.SWITCH(G18, $Q$10, $R$10, $Q$11, $R$11, $Q$12, $R$12, $Q$13, $R$13, $Q$14, $R$14, $Q$15, $R$15, $Q$16, $R$16, $Q$17, $R$17, $Q$18, $R$18,$Q$19,$R$19,$Q$20,$R$20,$Q$21,$R$21,$Q$22,$R$22,$Q$23,$R$23,$Q$24,$R$24), 0)} -> 0 | K18: =IFERROR(H18*(1-J18),0) -> 0 | L18: =IFERROR(K18*E18,0)/$L$5 -> 0 | M18: =IFERROR(K18*E18,0) -> 0 | N18: {=IFERROR(K18*(1+IFERROR(_xlfn.SWITCH(G18, $Q$10, $S$10, $Q$11, $S$11, $Q$12, $S$12, $Q$13, $S$13, $Q$14, $S$14, $Q$15, $S$15, $Q$16, $S$16, $Q$17, $S$17, $Q$18, $S$18,$Q$19,$S$19,$Q$20,$S$20,$Q$21,$S$21,$Q$22,$S$22,$Q$23,$S$23,$Q$24,$S$24), $S$10))*bp, 0)} -> 0 | O18: =IFERROR(N18*E18,0) -> 0 | Q18: Training and Onboarding | R18: 0 | S18: =iserv -> 0.0701 | U18: CRM | V18: ='Opportunity_Name USD'!$E$6 -> 0 | W18: =SUMIF('Opp Name'!$F:$F,Table142[[#This Row],[Group]],'Opp Name'!$I:$I) -> 0 | X18: =W18/V18 -> #DIV/0! | Y18: =SUMIF('Opp Name'!$F:$F,Table142[[#This Row],[Group]],'Opp Name'!$M:$M) -> 0 | Z18: =Y18/V18 -> #DIV/0!
B19: 14 | I19: =H19*E19 -> 0 | J19: {=IFERROR(_xlfn.SWITCH(G19, $Q$10, $R$10, $Q$11, $R$11, $Q$12, $R$12, $Q$13, $R$13, $Q$14, $R$14, $Q$15, $R$15, $Q$16, $R$16, $Q$17, $R$17, $Q$18, $R$18,$Q$19,$R$19,$Q$20,$R$20,$Q$21,$R$21,$Q$22,$R$22,$Q$23,$R$23,$Q$24,$R$24), 0)} -> 0 | K19: =IFERROR(H19*(1-J19),0) -> 0 | L19: =IFERROR(K19*E19,0)/$L$5 -> 0 | M19: =IFERROR(K19*E19,0) -> 0 | N19: {=IFERROR(K19*(1+IFERROR(_xlfn.SWITCH(G19, $Q$10, $S$10, $Q$11, $S$11, $Q$12, $S$12, $Q$13, $S$13, $Q$14, $S$14, $Q$15, $S$15, $Q$16, $S$16, $Q$17, $S$17, $Q$18, $S$18,$Q$19,$S$19,$Q$20,$S$20,$Q$21,$S$21,$Q$22,$S$22,$Q$23,$S$23,$Q$24,$S$24), $S$10))*bp, 0)} -> 0 | O19: =IFERROR(N19*E19,0) -> 0 | Q19: Connectivity MRC | R19: 0 | S19: =iconn -> 0.11 | U19: Add-on | V19: ='Opportunity_Name USD'!$E$6 -> 0 | W19: =SUMIF('Opp Name'!$F:$F,Table142[[#This Row],[Group]],'Opp Name'!$I:$I) -> 0 | X19: =W19/V19 -> #DIV/0! | Y19: =SUMIF('Opp Name'!$F:$F,Table142[[#This Row],[Group]],'Opp Name'!$M:$M) -> 0 | Z19: =Y19/V19 -> #DIV/0!
B20: 15 | I20: =H20*E20 -> 0 | J20: {=IFERROR(_xlfn.SWITCH(G20, $Q$10, $R$10, $Q$11, $R$11, $Q$12, $R$12, $Q$13, $R$13, $Q$14, $R$14, $Q$15, $R$15, $Q$16, $R$16, $Q$17, $R$17, $Q$18, $R$18,$Q$19,$R$19,$Q$20,$R$20,$Q$21,$R$21,$Q$22,$R$22,$Q$23,$R$23,$Q$24,$R$24), 0)} -> 0 | K20: =IFERROR(H20*(1-J20),0) -> 0 | L20: =IFERROR(K20*E20,0)/$L$5 -> 0 | M20: =IFERROR(K20*E20,0) -> 0 | N20: {=IFERROR(K20*(1+IFERROR(_xlfn.SWITCH(G20, $Q$10, $S$10, $Q$11, $S$11, $Q$12, $S$12, $Q$13, $S$13, $Q$14, $S$14, $Q$15, $S$15, $Q$16, $S$16, $Q$17, $S$17, $Q$18, $S$18,$Q$19,$S$19,$Q$20,$S$20,$Q$21,$S$21,$Q$22,$S$22,$Q$23,$S$23,$Q$24,$S$24), $S$10))*bp, 0)} -> 0 | O20: =IFERROR(N20*E20,0) -> 0 | Q20: Connectivity NRC | R20: 0 | S20: =iconn -> 0.11 | U20: Others | V20: ='Opportunity_Name USD'!$E$6 -> 0 | W20: =SUMIF('Opp Name'!$F:$F,Table142[[#This Row],[Group]],'Opp Name'!$I:$I) -> 0 | X20: =W20/V20 -> #DIV/0! | Y20: =SUMIF('Opp Name'!$F:$F,Table142[[#This Row],[Group]],'Opp Name'!$M:$M) -> 0 | Z20: =Y20/V20 -> #DIV/0!
B21: 16 | I21: =H21*E21 -> 0 | J21: {=IFERROR(_xlfn.SWITCH(G21, $Q$10, $R$10, $Q$11, $R$11, $Q$12, $R$12, $Q$13, $R$13, $Q$14, $R$14, $Q$15, $R$15, $Q$16, $R$16, $Q$17, $R$17, $Q$18, $R$18,$Q$19,$R$19,$Q$20,$R$20,$Q$21,$R$21,$Q$22,$R$22,$Q$23,$R$23,$Q$24,$R$24), 0)} -> 0 | K21: =IFERROR(H21*(1-J21),0) -> 0 | L21: =IFERROR(K21*E21,0)/$L$5 -> 0 | M21: =IFERROR(K21*E21,0) -> 0 | N21: {=IFERROR(K21*(1+IFERROR(_xlfn.SWITCH(G21, $Q$10, $S$10, $Q$11, $S$11, $Q$12, $S$12, $Q$13, $S$13, $Q$14, $S$14, $Q$15, $S$15, $Q$16, $S$16, $Q$17, $S$17, $Q$18, $S$18,$Q$19,$S$19,$Q$20,$S$20,$Q$21,$S$21,$Q$22,$S$22,$Q$23,$S$23,$Q$24,$S$24), $S$10))*bp, 0)} -> 0 | O21: =IFERROR(N21*E21,0) -> 0 | Q21: Usage | R21: 0 | S21: =isaas -> 0.1383 | T21: #0C769E | V21: ='Opportunity_Name USD'!$E$6 -> 0 | W21: =SUMIF('Opp Name'!$F:$F,Table142[[#This Row],[Group]],'Opp Name'!$I:$I) -> 0 | X21: =W21/V21 -> #DIV/0! | Y21: =SUMIF('Opp Name'!$F:$F,Table142[[#This Row],[Group]],'Opp Name'!$M:$M) -> 0 | Z21: =Y21/V21 -> #DIV/0!
B22: 17 | I22: =H22*E22 -> 0 | J22: {=IFERROR(_xlfn.SWITCH(G22, $Q$10, $R$10, $Q$11, $R$11, $Q$12, $R$12, $Q$13, $R$13, $Q$14, $R$14, $Q$15, $R$15, $Q$16, $R$16, $Q$17, $R$17, $Q$18, $R$18,$Q$19,$R$19,$Q$20,$R$20,$Q$21,$R$21,$Q$22,$R$22,$Q$23,$R$23,$Q$24,$R$24), 0)} -> 0 | K22: =IFERROR(H22*(1-J22),0) -> 0 | L22: =IFERROR(K22*E22,0)/$L$5 -> 0 | M22: =IFERROR(K22*E22,0) -> 0 | N22: {=IFERROR(K22*(1+IFERROR(_xlfn.SWITCH(G22, $Q$10, $S$10, $Q$11, $S$11, $Q$12, $S$12, $Q$13, $S$13, $Q$14, $S$14, $Q$15, $S$15, $Q$16, $S$16, $Q$17, $S$17, $Q$18, $S$18,$Q$19,$S$19,$Q$20,$S$20,$Q$21,$S$21,$Q$22,$S$22,$Q$23,$S$23,$Q$24,$S$24), $S$10))*bp, 0)} -> 0 | O22: =IFERROR(N22*E22,0) -> 0 | Q22: Schedule B | R22: 0 | S22: =isaas -> 0.1383 | T22: #92D050 | V22: ='Opportunity_Name USD'!$E$6 -> 0 | W22: =SUMIF('Opp Name'!$F:$F,Table142[[#This Row],[Group]],'Opp Name'!$I:$I) -> 0 | X22: =W22/V22 -> #DIV/0! | Y22: =SUMIF('Opp Name'!$F:$F,Table142[[#This Row],[Group]],'Opp Name'!$M:$M) -> 0 | Z22: =Y22/V22 -> #DIV/0!
B23: 18 | I23: =H23*E23 -> 0 | J23: {=IFERROR(_xlfn.SWITCH(G23, $Q$10, $R$10, $Q$11, $R$11, $Q$12, $R$12, $Q$13, $R$13, $Q$14, $R$14, $Q$15, $R$15, $Q$16, $R$16, $Q$17, $R$17, $Q$18, $R$18,$Q$19,$R$19,$Q$20,$R$20,$Q$21,$R$21,$Q$22,$R$22,$Q$23,$R$23,$Q$24,$R$24), 0)} -> 0 | K23: =IFERROR(H23*(1-J23),0) -> 0 | L23: =IFERROR(K23*E23,0)/$L$5 -> 0 | M23: =IFERROR(K23*E23,0) -> 0 | N23: {=IFERROR(K23*(1+IFERROR(_xlfn.SWITCH(G23, $Q$10, $S$10, $Q$11, $S$11, $Q$12, $S$12, $Q$13, $S$13, $Q$14, $S$14, $Q$15, $S$15, $Q$16, $S$16, $Q$17, $S$17, $Q$18, $S$18,$Q$19,$S$19,$Q$20,$S$20,$Q$21,$S$21,$Q$22,$S$22,$Q$23,$S$23,$Q$24,$S$24), $S$10))*bp, 0)} -> 0 | O23: =IFERROR(N23*E23,0) -> 0 | Q23: Storage | R23: 0 | S23: =isaas -> 0.1383 | T23: #E49EDD | V23: ='Opportunity_Name USD'!$E$6 -> 0 | W23: =SUMIF('Opp Name'!$F:$F,Table142[[#This Row],[Group]],'Opp Name'!$I:$I) -> 0 | X23: =W23/V23 -> #DIV/0! | Y23: =SUMIF('Opp Name'!$F:$F,Table142[[#This Row],[Group]],'Opp Name'!$M:$M) -> 0 | Z23: =Y23/V23 -> #DIV/0!
B24: 19 | I24: =H24*E24 -> 0 | J24: {=IFERROR(_xlfn.SWITCH(G24, $Q$10, $R$10, $Q$11, $R$11, $Q$12, $R$12, $Q$13, $R$13, $Q$14, $R$14, $Q$15, $R$15, $Q$16, $R$16, $Q$17, $R$17, $Q$18, $R$18,$Q$19,$R$19,$Q$20,$R$20,$Q$21,$R$21,$Q$22,$R$22,$Q$23,$R$23,$Q$24,$R$24), 0)} -> 0 | K24: =IFERROR(H24*(1-J24),0) -> 0 | L24: =IFERROR(K24*E24,0)/$L$5 -> 0 | M24: =IFERROR(K24*E24,0) -> 0 | N24: {=IFERROR(K24*(1+IFERROR(_xlfn.SWITCH(G24, $Q$10, $S$10, $Q$11, $S$11, $Q$12, $S$12, $Q$13, $S$13, $Q$14, $S$14, $Q$15, $S$15, $Q$16, $S$16, $Q$17, $S$17, $Q$18, $S$18,$Q$19,$S$19,$Q$20,$S$20,$Q$21,$S$21,$Q$22,$S$22,$Q$23,$S$23,$Q$24,$S$24), $S$10))*bp, 0)} -> 0 | O24: =IFERROR(N24*E24,0) -> 0 | R24: 0 | S24: =isaas -> 0.1383 | U24: Total | W24: =SUBTOTAL(109,Table142[List Price BRL]) -> 0 | Y24: =SUBTOTAL(109,Table142[Discounted Price BRL]) -> 0
B25: 20 | I25: =H25*E25 -> 0 | J25: {=IFERROR(_xlfn.SWITCH(G25, $Q$10, $R$10, $Q$11, $R$11, $Q$12, $R$12, $Q$13, $R$13, $Q$14, $R$14, $Q$15, $R$15, $Q$16, $R$16, $Q$17, $R$17, $Q$18, $R$18,$Q$19,$R$19,$Q$20,$R$20,$Q$21,$R$21,$Q$22,$R$22,$Q$23,$R$23,$Q$24,$R$24), 0)} -> 0 | K25: =IFERROR(H25*(1-J25),0) -> 0 | L25: =IFERROR(K25*E25,0)/$L$5 -> 0 | M25: =IFERROR(K25*E25,0) -> 0 | N25: {=IFERROR(K25*(1+IFERROR(_xlfn.SWITCH(G25, $Q$10, $S$10, $Q$11, $S$11, $Q$12, $S$12, $Q$13, $S$13, $Q$14, $S$14, $Q$15, $S$15, $Q$16, $S$16, $Q$17, $S$17, $Q$18, $S$18,$Q$19,$S$19,$Q$20,$S$20,$Q$21,$S$21,$Q$22,$S$22,$Q$23,$S$23,$Q$24,$S$24), $S$10))*bp, 0)} -> 0 | O25: =IFERROR(N25*E25,0) -> 0
B26: 21 | I26: =H26*E26 -> 0 | J26: {=IFERROR(_xlfn.SWITCH(G26, $Q$10, $R$10, $Q$11, $R$11, $Q$12, $R$12, $Q$13, $R$13, $Q$14, $R$14, $Q$15, $R$15, $Q$16, $R$16, $Q$17, $R$17, $Q$18, $R$18,$Q$19,$R$19,$Q$20,$R$20,$Q$21,$R$21,$Q$22,$R$22,$Q$23,$R$23,$Q$24,$R$24), 0)} -> 0 | K26: =IFERROR(H26*(1-J26),0) -> 0 | L26: =IFERROR(K26*E26,0)/$L$5 -> 0 | M26: =IFERROR(K26*E26,0) -> 0 | N26: {=IFERROR(K26*(1+IFERROR(_xlfn.SWITCH(G26, $Q$10, $S$10, $Q$11, $S$11, $Q$12, $S$12, $Q$13, $S$13, $Q$14, $S$14, $Q$15, $S$15, $Q$16, $S$16, $Q$17, $S$17, $Q$18, $S$18,$Q$19,$S$19,$Q$20,$S$20,$Q$21,$S$21,$Q$22,$S$22,$Q$23,$S$23,$Q$24,$S$24), $S$10))*bp, 0)} -> 0 | O26: =IFERROR(N26*E26,0) -> 0
I27: =SUM(I6:I26) -> 0 | L27: =SUM(L6:L26) -> 0 | M27: =SUM(M6:M26) -> 0 | O27: =SUM(O6:O26) -> 0
L28: =L27/E6 -> #DIV/0!
B29: SOFTWARE USAGE PRODUCTS | H29: PRICE LIST | J29: FOB NET PRICE | N29: SELL PRICE (WITH TAXES)
B30: # | C30: Product | D30: SKU | E30: Quantity | F30: Group | G30: Prod Category Discount | H30: Unit Partner Price | I30: Total Partner Price | J30: Additional Discount | K30: Unit Price (FOB) | L30: =$L$5 -> 1 | M30: FOB NET | N30: Unit Sell Price | O30: Total Sell Price
B31: 1 | I31: =H31*E31 -> 0 | J31: {=IFERROR(_xlfn.SWITCH(G31, $Q$10, $R$10, $Q$11, $R$11, $Q$12, $R$12, $Q$13, $R$13, $Q$14, $R$14, $Q$15, $R$15, $Q$16, $R$16, $Q$17, $R$17, $Q$18, $R$18,$Q$19,$R$19,$Q$20,$R$20,$Q$21,$R$21,$Q$22,$R$22,$Q$23,$R$23,$Q$24,$R$24), 0)} -> 0 | K31: =IFERROR(H31*(1-J31),0) -> 0 | L31: =IFERROR(K31*E31,0)/$L$5 -> 0 | M31: =IFERROR(K31*E31,0) -> 0 | N31: {=IFERROR(K31*(1+IFERROR(_xlfn.SWITCH(G31, $Q$10, $S$10, $Q$11, $S$11, $Q$12, $S$12, $Q$13, $S$13, $Q$14, $S$14, $Q$15, $S$15, $Q$16, $S$16, $Q$17, $S$17, $Q$18, $S$18,$Q$19,$S$19,$Q$20,$S$20,$Q$21,$S$21,$Q$22,$S$22,$Q$23,$S$23,$Q$24,$S$24), $S$10))*bp, 0)} -> 0 | O31: =IFERROR(N31*E31,0) -> 0
B32: 2 | I32: =H32*E32 -> 0 | J32: {=IFERROR(_xlfn.SWITCH(G32, $Q$10, $R$10, $Q$11, $R$11, $Q$12, $R$12, $Q$13, $R$13, $Q$14, $R$14, $Q$15, $R$15, $Q$16, $R$16, $Q$17, $R$17, $Q$18, $R$18,$Q$19,$R$19,$Q$20,$R$20,$Q$21,$R$21,$Q$22,$R$22,$Q$23,$R$23,$Q$24,$R$24), 0)} -> 0 | K32: =IFERROR(H32*(1-J32),0) -> 0 | L32: =IFERROR(K32*E32,0)/$L$5 -> 0 | M32: =IFERROR(K32*E32,0) -> 0 | N32: {=IFERROR(K32*(1+IFERROR(_xlfn.SWITCH(G32, $Q$10, $S$10, $Q$11, $S$11, $Q$12, $S$12, $Q$13, $S$13, $Q$14, $S$14, $Q$15, $S$15, $Q$16, $S$16, $Q$17, $S$17, $Q$18, $S$18,$Q$19,$S$19,$Q$20,$S$20,$Q$21,$S$21,$Q$22,$S$22,$Q$23,$S$23,$Q$24,$S$24), $S$10))*bp, 0)} -> 0 | O32: =IFERROR(N32*E32,0) -> 0
B33: 3 | I33: =H33*E33 -> 0 | J33: {=IFERROR(_xlfn.SWITCH(G33, $Q$10, $R$10, $Q$11, $R$11, $Q$12, $R$12, $Q$13, $R$13, $Q$14, $R$14, $Q$15, $R$15, $Q$16, $R$16, $Q$17, $R$17, $Q$18, $R$18,$Q$19,$R$19,$Q$20,$R$20,$Q$21,$R$21,$Q$22,$R$22,$Q$23,$R$23,$Q$24,$R$24), 0)} -> 0 | K33: =IFERROR(H33*(1-J33),0) -> 0 | L33: =IFERROR(K33*E33,0)/$L$5 -> 0 | M33: =IFERROR(K33*E33,0) -> 0 | N33: {=IFERROR(K33*(1+IFERROR(_xlfn.SWITCH(G33, $Q$10, $S$10, $Q$11, $S$11, $Q$12, $S$12, $Q$13, $S$13, $Q$14, $S$14, $Q$15, $S$15, $Q$16, $S$16, $Q$17, $S$17, $Q$18, $S$18,$Q$19,$S$19,$Q$20,$S$20,$Q$21,$S$21,$Q$22,$S$22,$Q$23,$S$23,$Q$24,$S$24), $S$10))*bp, 0)} -> 0 | O33: =IFERROR(N33*E33,0) -> 0
B34: 4 | I34: =H34*E34 -> 0 | J34: {=IFERROR(_xlfn.SWITCH(G34, $Q$10, $R$10, $Q$11, $R$11, $Q$12, $R$12, $Q$13, $R$13, $Q$14, $R$14, $Q$15, $R$15, $Q$16, $R$16, $Q$17, $R$17, $Q$18, $R$18,$Q$19,$R$19,$Q$20,$R$20,$Q$21,$R$21,$Q$22,$R$22,$Q$23,$R$23,$Q$24,$R$24), 0)} -> 0 | K34: =IFERROR(H34*(1-J34),0) -> 0 | L34: =IFERROR(K34*E34,0)/$L$5 -> 0 | M34: =IFERROR(K34*E34,0) -> 0 | N34: {=IFERROR(K34*(1+IFERROR(_xlfn.SWITCH(G34, $Q$10, $S$10, $Q$11, $S$11, $Q$12, $S$12, $Q$13, $S$13, $Q$14, $S$14, $Q$15, $S$15, $Q$16, $S$16, $Q$17, $S$17, $Q$18, $S$18,$Q$19,$S$19,$Q$20,$S$20,$Q$21,$S$21,$Q$22,$S$22,$Q$23,$S$23,$Q$24,$S$24), $S$10))*bp, 0)} -> 0 | O34: =IFERROR(N34*E34,0) -> 0
B35: 5 | I35: =H35*E35 -> 0 | J35: {=IFERROR(_xlfn.SWITCH(G35, $Q$10, $R$10, $Q$11, $R$11, $Q$12, $R$12, $Q$13, $R$13, $Q$14, $R$14, $Q$15, $R$15, $Q$16, $R$16, $Q$17, $R$17, $Q$18, $R$18,$Q$19,$R$19,$Q$20,$R$20,$Q$21,$R$21,$Q$22,$R$22,$Q$23,$R$23,$Q$24,$R$24), 0)} -> 0 | K35: =IFERROR(H35*(1-J35),0) -> 0 | L35: =IFERROR(K35*E35,0)/$L$5 -> 0 | M35: =IFERROR(K35*E35,0) -> 0 | N35: {=IFERROR(K35*(1+IFERROR(_xlfn.SWITCH(G35, $Q$10, $S$10, $Q$11, $S$11, $Q$12, $S$12, $Q$13, $S$13, $Q$14, $S$14, $Q$15, $S$15, $Q$16, $S$16, $Q$17, $S$17, $Q$18, $S$18,$Q$19,$S$19,$Q$20,$S$20,$Q$21,$S$21,$Q$22,$S$22,$Q$23,$S$23,$Q$24,$S$24), $S$10))*bp, 0)} -> 0 | O35: =IFERROR(N35*E35,0) -> 0
B36: 6 | I36: =H36*E36 -> 0 | J36: {=IFERROR(_xlfn.SWITCH(G36, $Q$10, $R$10, $Q$11, $R$11, $Q$12, $R$12, $Q$13, $R$13, $Q$14, $R$14, $Q$15, $R$15, $Q$16, $R$16, $Q$17, $R$17, $Q$18, $R$18,$Q$19,$R$19,$Q$20,$R$20,$Q$21,$R$21,$Q$22,$R$22,$Q$23,$R$23,$Q$24,$R$24), 0)} -> 0 | K36: =IFERROR(H36*(1-J36),0) -> 0 | L36: =IFERROR(K36*E36,0)/$L$5 -> 0 | M36: =IFERROR(K36*E36,0) -> 0 | N36: {=IFERROR(K36*(1+IFERROR(_xlfn.SWITCH(G36, $Q$10, $S$10, $Q$11, $S$11, $Q$12, $S$12, $Q$13, $S$13, $Q$14, $S$14, $Q$15, $S$15, $Q$16, $S$16, $Q$17, $S$17, $Q$18, $S$18,$Q$19,$S$19,$Q$20,$S$20,$Q$21,$S$21,$Q$22,$S$22,$Q$23,$S$23,$Q$24,$S$24), $S$10))*bp, 0)} -> 0 | O36: =IFERROR(N36*E36,0) -> 0
B37: 7 | I37: =H37*E37 -> 0 | J37: {=IFERROR(_xlfn.SWITCH(G37, $Q$10, $R$10, $Q$11, $R$11, $Q$12, $R$12, $Q$13, $R$13, $Q$14, $R$14, $Q$15, $R$15, $Q$16, $R$16, $Q$17, $R$17, $Q$18, $R$18,$Q$19,$R$19,$Q$20,$R$20,$Q$21,$R$21,$Q$22,$R$22,$Q$23,$R$23,$Q$24,$R$24), 0)} -> 0 | K37: =IFERROR(H37*(1-J37),0) -> 0 | L37: =IFERROR(K37*E37,0)/$L$5 -> 0 | M37: =IFERROR(K37*E37,0) -> 0 | N37: {=IFERROR(K37*(1+IFERROR(_xlfn.SWITCH(G37, $Q$10, $S$10, $Q$11, $S$11, $Q$12, $S$12, $Q$13, $S$13, $Q$14, $S$14, $Q$15, $S$15, $Q$16, $S$16, $Q$17, $S$17, $Q$18, $S$18,$Q$19,$S$19,$Q$20,$S$20,$Q$21,$S$21,$Q$22,$S$22,$Q$23,$S$23,$Q$24,$S$24), $S$10))*bp, 0)} -> 0 | O37: =IFERROR(N37*E37,0) -> 0
B38: 8 | I38: =H38*E38 -> 0 | J38: {=IFERROR(_xlfn.SWITCH(G38, $Q$10, $R$10, $Q$11, $R$11, $Q$12, $R$12, $Q$13, $R$13, $Q$14, $R$14, $Q$15, $R$15, $Q$16, $R$16, $Q$17, $R$17, $Q$18, $R$18,$Q$19,$R$19,$Q$20,$R$20,$Q$21,$R$21,$Q$22,$R$22,$Q$23,$R$23,$Q$24,$R$24), 0)} -> 0 | K38: =IFERROR(H38*(1-J38),0) -> 0 | L38: =IFERROR(K38*E38,0)/$L$5 -> 0 | M38: =IFERROR(K38*E38,0) -> 0 | N38: {=IFERROR(K38*(1+IFERROR(_xlfn.SWITCH(G38, $Q$10, $S$10, $Q$11, $S$11, $Q$12, $S$12, $Q$13, $S$13, $Q$14, $S$14, $Q$15, $S$15, $Q$16, $S$16, $Q$17, $S$17, $Q$18, $S$18,$Q$19,$S$19,$Q$20,$S$20,$Q$21,$S$21,$Q$22,$S$22,$Q$23,$S$23,$Q$24,$S$24), $S$10))*bp, 0)} -> 0 | O38: =IFERROR(N38*E38,0) -> 0
B39: 9 | I39: =H39*E39 -> 0 | J39: {=IFERROR(_xlfn.SWITCH(G39, $Q$10, $R$10, $Q$11, $R$11, $Q$12, $R$12, $Q$13, $R$13, $Q$14, $R$14, $Q$15, $R$15, $Q$16, $R$16, $Q$17, $R$17, $Q$18, $R$18,$Q$19,$R$19,$Q$20,$R$20,$Q$21,$R$21,$Q$22,$R$22,$Q$23,$R$23,$Q$24,$R$24), 0)} -> 0 | K39: =IFERROR(H39*(1-J39),0) -> 0 | L39: =IFERROR(K39*E39,0)/$L$5 -> 0 | M39: =IFERROR(K39*E39,0) -> 0 | N39: {=IFERROR(K39*(1+IFERROR(_xlfn.SWITCH(G39, $Q$10, $S$10, $Q$11, $S$11, $Q$12, $S$12, $Q$13, $S$13, $Q$14, $S$14, $Q$15, $S$15, $Q$16, $S$16, $Q$17, $S$17, $Q$18, $S$18,$Q$19,$S$19,$Q$20,$S$20,$Q$21,$S$21,$Q$22,$S$22,$Q$23,$S$23,$Q$24,$S$24), $S$10))*bp, 0)} -> 0 | O39: =IFERROR(N39*E39,0) -> 0
B40: 10 | I40: =H40*E40 -> 0 | J40: {=IFERROR(_xlfn.SWITCH(G40, $Q$10, $R$10, $Q$11, $R$11, $Q$12, $R$12, $Q$13, $R$13, $Q$14, $R$14, $Q$15, $R$15, $Q$16, $R$16, $Q$17, $R$17, $Q$18, $R$18,$Q$19,$R$19,$Q$20,$R$20,$Q$21,$R$21,$Q$22,$R$22,$Q$23,$R$23,$Q$24,$R$24), 0)} -> 0 | K40: =IFERROR(H40*(1-J40),0) -> 0 | L40: =IFERROR(K40*E40,0)/$L$5 -> 0 | M40: =IFERROR(K40*E40,0) -> 0 | N40: {=IFERROR(K40*(1+IFERROR(_xlfn.SWITCH(G40, $Q$10, $S$10, $Q$11, $S$11, $Q$12, $S$12, $Q$13, $S$13, $Q$14, $S$14, $Q$15, $S$15, $Q$16, $S$16, $Q$17, $S$17, $Q$18, $S$18,$Q$19,$S$19,$Q$20,$S$20,$Q$21,$S$21,$Q$22,$S$22,$Q$23,$S$23,$Q$24,$S$24), $S$10))*bp, 0)} -> 0 | O40: =IFERROR(N40*E40,0) -> 0
B41: 11 | I41: =H41*E41 -> 0 | J41: {=IFERROR(_xlfn.SWITCH(G41, $Q$10, $R$10, $Q$11, $R$11, $Q$12, $R$12, $Q$13, $R$13, $Q$14, $R$14, $Q$15, $R$15, $Q$16, $R$16, $Q$17, $R$17, $Q$18, $R$18,$Q$19,$R$19,$Q$20,$R$20,$Q$21,$R$21,$Q$22,$R$22,$Q$23,$R$23,$Q$24,$R$24), 0)} -> 0 | K41: =IFERROR(H41*(1-J41),0) -> 0 | L41: =IFERROR(K41*E41,0)/$L$5 -> 0 | M41: =IFERROR(K41*E41,0) -> 0 | N41: {=IFERROR(K41*(1+IFERROR(_xlfn.SWITCH(G41, $Q$10, $S$10, $Q$11, $S$11, $Q$12, $S$12, $Q$13, $S$13, $Q$14, $S$14, $Q$15, $S$15, $Q$16, $S$16, $Q$17, $S$17, $Q$18, $S$18,$Q$19,$S$19,$Q$20,$S$20,$Q$21,$S$21,$Q$22,$S$22,$Q$23,$S$23,$Q$24,$S$24), $S$10))*bp, 0)} -> 0 | O41: =IFERROR(N41*E41,0) -> 0
B42: 12 | I42: =H42*E42 -> 0 | J42: {=IFERROR(_xlfn.SWITCH(G42, $Q$10, $R$10, $Q$11, $R$11, $Q$12, $R$12, $Q$13, $R$13, $Q$14, $R$14, $Q$15, $R$15, $Q$16, $R$16, $Q$17, $R$17, $Q$18, $R$18,$Q$19,$R$19,$Q$20,$R$20,$Q$21,$R$21,$Q$22,$R$22,$Q$23,$R$23,$Q$24,$R$24), 0)} -> 0 | K42: =IFERROR(H42*(1-J42),0) -> 0 | L42: =IFERROR(K42*E42,0)/$L$5 -> 0 | M42: =IFERROR(K42*E42,0) -> 0 | N42: {=IFERROR(K42*(1+IFERROR(_xlfn.SWITCH(G42, $Q$10, $S$10, $Q$11, $S$11, $Q$12, $S$12, $Q$13, $S$13, $Q$14, $S$14, $Q$15, $S$15, $Q$16, $S$16, $Q$17, $S$17, $Q$18, $S$18,$Q$19,$S$19,$Q$20,$S$20,$Q$21,$S$21,$Q$22,$S$22,$Q$23,$S$23,$Q$24,$S$24), $S$10))*bp, 0)} -> 0 | O42: =IFERROR(N42*E42,0) -> 0
...

Sheet Sobre o Uso do Template
B2: Recomendações de uso
B3: - Manter uma cópia original desse template e "passar" a quote para a planilha em outro arquivo cópia
B4: Mudanças na tabela
B5: - Ao colocar a categoria em "Prod Category", formata automaticamente a cor, a % do desconto e a formatação da célula de desconto
B6: - Apaga automaticamente ao remover a categoria do produto
B7: - Funciona apenas para as tabelas que possuem a coluna "Prod Category"
B9: Benefícios
B10: - Não precisa mudar a porcentagem do desconto em cada célula, é automático
B11: - Formatações automáticas
B13: Pontos Negativos
B14: - Ao alterar manualmente o desconto, fórmula é apagada. Procure possuir um arquivo desse template e realizar a quote em uma cópia
